Workbook

Sheet PortalFlow4TP
B1: Files
A2: Hour | B2: 1 | C2: 2 | D2: 3 | E2: 4 | F2: 5 | G2: 6 | H2: 7 | I2: 8 | J2: 9 | K2: 10 | L2: 11 | M2: 12 | N2: 13 | O2: 14 | P2: 15 | Q2: 16 | R2: 17 | S2: 18 | T2: 19 | U2: 20 | V2: 21 | W2: 22 | X2: 23 | Y2: 24 | Z2: 25 | AA2: 26 | AB2: 27 | AC2: 28 | AD2: 29 | AE2: 30 | AF2: 31 | AG2: 32 | AH2: 33 | AI2: 34 | AJ2: 35 | AK2: 36 | AL2: =AK2+1 -> 37 | AM2: =AL2+1 -> 38 | AN2: =AM2+1 -> 39 | AO2: =AN2+1 -> 40 | AP2: =AO2+1 -> 41 | AQ2: =AP2+1 -> 42 | AR2: =AQ2+1 -> 43 | AS2: =AR2+1 -> 44 | ... CJ2: =CI2+1 -> 87 | CK2: HOUR | CL2: MEAN | CM2: SDEV | CN2: STD ERROR
A3: 0 | B3: =IVCFlow!B3-ArterialFlow!B3 -> 1.0602113 | C3: =IVCFlow!C3-ArterialFlow!C3 -> 0.86667412 | D3: =IVCFlow!D3-ArterialFlow!D3 -> 0.8413 | E3: =IVCFlow!E3-ArterialFlow!E3 -> 1.0221745 | F3: =IVCFlow!F3-ArterialFlow!F3 -> 1.0137754 | G3: =IVCFlow!G3-ArterialFlow!G3 -> 1.0137754 | H3: =IVCFlow!H3-ArterialFlow!H3 -> 1.3278772 | I3: =IVCFlow!I3-ArterialFlow!I3 -> 1.070831 | ... Z3: =IVCFlow!Z3-ArterialFlow!Z3 -> 1.045448 | AB3: =IVCFlow!AB3-ArterialFlow!AB3 -> 1.2756274 | AC3: =IVCFlow!AC3-ArterialFlow!AC3 -> 1.1275933 | AD3: =IVCFlow!AD3-ArterialFlow!AD3 -> 1.0595216 | AE3: =IVCFlow!AE3-ArterialFlow!AE3 -> 1.1230434 | AF3: =IVCFlow!AF3-ArterialFlow!AF3 -> 1.1509505 | AG3: =IVCFlow!AG3-ArterialFlow!AG3 -> 1.1249542 | AH3: =IVCFlow!AH3-ArterialFlow!AH3 -> 1.3101891 | AI3: =IVCFlow!AI3-ArterialFlow!AI3 -> 1.2260685 | ... AW3: =IVCFlow!AW3-ArterialFlow!AW3 -> 1.3181083 | AY3: =IVCFlow!AY3-ArterialFlow!AY3 -> 1.2576139 | AZ3: =IVCFlow!AZ3-ArterialFlow!AZ3 -> 1.2011972 | BA3: =IVCFlow!BA3-ArterialFlow!BA3 -> 1.0290056 | BB3: =IVCFlow!BB3-ArterialFlow!BB3 -> 0.95148531 | BC3: =IVCFlow!BC3-ArterialFlow!BC3 -> 1.1852493 | BD3: =IVCFlow!BD3-ArterialFlow!BD3 -> 0.84749552 | BE3: =IVCFlow!BE3-ArterialFlow!BE3 -> 1.0622368 | BF3: =IVCFlow!BF3-ArterialFlow!BF3 -> 1.0390345 | ... BY3: =IVCFlow!BY3-ArterialFlow!BY3 -> 1.2283163 | BZ3: 1.6966282 | CA3: =IVCFlow!CA3-ArterialFlow!CA3 -> 0.9791581 | CB3: =IVCFlow!CB3-ArterialFlow!CB3 -> 1.0363647 | CC3: =IVCFlow!CC3-ArterialFlow!CC3 -> 0.96004211 | CD3: =IVCFlow!CD3-ArterialFlow!CD3 -> 1.1128127 | CE3: =IVCFlow!CE3-ArterialFlow!CE3 -> 1.1395518 | CF3: =IVCFlow!CF3-ArterialFlow!CF3 -> 1.0754075 | CG3: =IVCFlow!CG3-ArterialFlow!CG3 -> 1.1823291 | CH3: =IVCFlow!CH3-ArterialFlow!CH3 -> 1.2576299 | ... CJ3: =IVCFlow!CJ3-ArterialFlow!CJ3 -> 1.0296414 | CK3: First Hour | CL3: =AVERAGE(B3:CJ3) -> 1.1179938 | CM3: =STDEV(B3:CJ3) -> 0.20466656 | CN3: =CM3/SQRT(COUNT(B3:CJ3)) -> 0.022199206
A4: 1 | B4: =IVCFlow!B4-ArterialFlow!B4 -> 1.0610643 | C4: =IVCFlow!C4-ArterialFlow!C4 -> 0.9052582 | D4: =IVCFlow!D4-ArterialFlow!D4 -> 1.0076972 | E4: =IVCFlow!E4-ArterialFlow!E4 -> 1.1695722 | F4: =IVCFlow!F4-ArterialFlow!F4 -> 1.0022345 | G4: =IVCFlow!G4-ArterialFlow!G4 -> 1.0022345 | H4: =IVCFlow!H4-ArterialFlow!H4 -> 1.1563434 | I4: =IVCFlow!I4-ArterialFlow!I4 -> 1.0467794 | ... Z4: =IVCFlow!Z4-ArterialFlow!Z4 -> 1.0792379 | AB4: =IVCFlow!AB4-ArterialFlow!AB4 -> 1.2904322 | AC4: =IVCFlow!AC4-ArterialFlow!AC4 -> 1.1100419 | AD4: =IVCFlow!AD4-ArterialFlow!AD4 -> 1.0785295 | AE4: =IVCFlow!AE4-ArterialFlow!AE4 -> 1.1311694 | AF4: =IVCFlow!AF4-ArterialFlow!AF4 -> 0.63652174 | AG4: =IVCFlow!AG4-ArterialFlow!AG4 -> 1.1350097 | AH4: =IVCFlow!AH4-ArterialFlow!AH4 -> 1.2725751 | AI4: =IVCFlow!AI4-ArterialFlow!AI4 -> 1.2517528 | ... AW4: =IVCFlow!AW4-ArterialFlow!AW4 -> 1.1452056 | AY4: =IVCFlow!AY4-ArterialFlow!AY4 -> 1.2884528 | AZ4: =IVCFlow!AZ4-ArterialFlow!AZ4 -> 1.1885488 | BA4: =IVCFlow!BA4-ArterialFlow!BA4 -> 1.0783857 | BB4: =IVCFlow!BB4-ArterialFlow!BB4 -> 1.0535178 | BC4: =IVCFlow!BC4-ArterialFlow!BC4 -> 1.2927582 | BD4: =IVCFlow!BD4-ArterialFlow!BD4 -> 1.0427286 | BE4: =IVCFlow!BE4-ArterialFlow!BE4 -> 1.0828814 | BF4: =IVCFlow!BF4-ArterialFlow!BF4 -> 1.0165712 | ... BY4: =IVCFlow!BY4-ArterialFlow!BY4 -> 1.1954555 | BZ4: 1.5452389 | CA4: =IVCFlow!CA4-ArterialFlow!CA4 -> 0.98915278 | CB4: =IVCFlow!CB4-ArterialFlow!CB4 -> 1.061315 | CC4: =IVCFlow!CC4-ArterialFlow!CC4 -> 1.0269624 | CD4: =IVCFlow!CD4-ArterialFlow!CD4 -> 1.1485714 | CE4: =IVCFlow!CE4-ArterialFlow!CE4 -> 1.1546556 | CF4: =IVCFlow!CF4-ArterialFlow!CF4 -> 1.202509 | CG4: =IVCFlow!CG4-ArterialFlow!CG4 -> 1.277325 | CH4: =IVCFlow!CH4-ArterialFlow!CH4 -> 1.2884528 | ... CJ4: =IVCFlow!CJ4-ArterialFlow!CJ4 -> 1.0790444 | CK4: Second Hour | CL4: =AVERAGE(B4:CJ4) -> 1.1181991 | CM4: =STDEV(B4:CJ4) -> 0.20215833 | CN4: =CM4/SQRT(COUNT(B4:CJ4)) -> 0.021927149
A5: 2 | B5: =IVCFlow!B5-ArterialFlow!B5 -> 0.96789869 | C5: =IVCFlow!C5-ArterialFlow!C5 -> 0.88602142 | D5: =IVCFlow!D5-ArterialFlow!D5 -> 0.95857546 | E5: =IVCFlow!E5-ArterialFlow!E5 -> 1.1473965 | F5: =IVCFlow!F5-ArterialFlow!F5 -> 0.94493292 | G5: =IVCFlow!G5-ArterialFlow!G5 -> 0.94493292 | H5: =IVCFlow!H5-ArterialFlow!H5 -> 1.1682912 | I5: =IVCFlow!I5-ArterialFlow!I5 -> 1.0405686 | ... Z5: =IVCFlow!Z5-ArterialFlow!Z5 -> 1.0916915 | AB5: =IVCFlow!AB5-ArterialFlow!AB5 -> 1.3117516 | AC5: =IVCFlow!AC5-ArterialFlow!AC5 -> 1.098695 | AD5: =IVCFlow!AD5-ArterialFlow!AD5 -> 1.1723529 | AE5: =IVCFlow!AE5-ArterialFlow!AE5 -> 1.1268205 | AF5: =IVCFlow!AF5-ArterialFlow!AF5 -> 1.0553493 | AG5: =IVCFlow!AG5-ArterialFlow!AG5 -> 1.14501 | AH5: =IVCFlow!AH5-ArterialFlow!AH5 -> 1.2269797 | AI5: =IVCFlow!AI5-ArterialFlow!AI5 -> 1.3163083 | ... AW5: =IVCFlow!AW5-ArterialFlow!AW5 -> 1.1791195 | AY5: =IVCFlow!AY5-ArterialFlow!AY5 -> 1.2940556 | AZ5: =IVCFlow!AZ5-ArterialFlow!AZ5 -> 1.2362406 | BA5: =IVCFlow!BA5-ArterialFlow!BA5 -> 1.1104222 | BB5: =IVCFlow!BB5-ArterialFlow!BB5 -> 1.0995336 | BC5: =IVCFlow!BC5-ArterialFlow!BC5 -> 1.2817928 | BD5: =IVCFlow!BD5-ArterialFlow!BD5 -> 0.98242244 | BE5: =IVCFlow!BE5-ArterialFlow!BE5 -> 1.0937577 | BF5: =IVCFlow!BF5-ArterialFlow!BF5 -> 1.029182 | ... BI5: =IVCFlow!BI5-ArterialFlow!BI5 -> 1.4073018 | BL5: =IVCFlow!BL5-ArterialFlow!BL5 -> 1.0937722 | BM5: =IVCFlow!BM5-ArterialFlow!BM5 -> 1.152875 | BN5: =IVCFlow!BN5-ArterialFlow!BN5 -> 1.1942583 | BO5: =IVCFlow!BO5-ArterialFlow!BO5 -> 1.117225 | BP5: =IVCFlow!BP5-ArterialFlow!BP5 -> 1.1268278 | BQ5: =IVCFlow!BQ5-ArterialFlow!BQ5 -> 1.0553348 | BR5: =IVCFlow!BR5-ArterialFlow!BR5 -> 1.2269722 | BS5: =IVCFlow!BS5-ArterialFlow!BS5 -> 1.1450433 | ... BY5: =IVCFlow!BY5-ArterialFlow!BY5 -> 1.2104112 | BZ5: 1.5884222 | CA5: =IVCFlow!CA5-ArterialFlow!CA5 -> 0.99475528 | CB5: =IVCFlow!CB5-ArterialFlow!CB5 -> 1.0493135 | CC5: =IVCFlow!CC5-ArterialFlow!CC5 -> 1.0720598 | CD5: =IVCFlow!CD5-ArterialFlow!CD5 -> 1.1490106 | CE5: =IVCFlow!CE5-ArterialFlow!CE5 -> 1.1664889 | CF5: =IVCFlow!CF5-ArterialFlow!CF5 -> 1.1997611 | CG5: =IVCFlow!CG5-ArterialFlow!CG5 -> 1.2881 | CH5: =IVCFlow!CH5-ArterialFlow!CH5 -> 1.2940556 | ... CJ5: =IVCFlow!CJ5-ArterialFlow!CJ5 -> 1.1104222 | CK5: Third Hour | CL5: =AVERAGE(B5:CJ5) -> 1.1236383 | CM5: =STDEV(B5:CJ5) -> 0.20618993 | CN5: =CM5/SQRT(COUNT(B5:CJ5)) -> 0.022632286
A6: 3 | B6: =IVCFlow!B6-ArterialFlow!B6 -> 0.69005656 | C6: =IVCFlow!C6-ArterialFlow!C6 -> 0.8657427 | D6: =IVCFlow!D6-ArterialFlow!D6 -> 0.96411896 | E6: =IVCFlow!E6-ArterialFlow!E6 -> 1.0816296 | F6: =IVCFlow!F6-ArterialFlow!F6 -> 1.0278889 | G6: =IVCFlow!G6-ArterialFlow!G6 -> 1.0278889 | H6: =IVCFlow!H6-ArterialFlow!H6 -> 1.1821107 | I6: =IVCFlow!I6-ArterialFlow!I6 -> 1.0338614 | ... Z6: =IVCFlow!Z6-ArterialFlow!Z6 -> 1.0506762 | AB6: =IVCFlow!AB6-ArterialFlow!AB6 -> 1.2689941 | AC6: =IVCFlow!AC6-ArterialFlow!AC6 -> 1.0906358 | AD6: =IVCFlow!AD6-ArterialFlow!AD6 -> 1.1786395 | AE6: =IVCFlow!AE6-ArterialFlow!AE6 -> 1.1818192 | AF6: =IVCFlow!AF6-ArterialFlow!AF6 -> 1.0445143 | AH6: =IVCFlow!AH6-ArterialFlow!AH6 -> 1.2314794 | AI6: =IVCFlow!AI6-ArterialFlow!AI6 -> 1.2666834 | AJ6: =IVCFlow!AJ6-ArterialFlow!AJ6 -> 1.1906232 | AK6: =IVCFlow!AK6-ArterialFlow!AK6 -> 1.0020323 | AL6: =IVCFlow!AL6-ArterialFlow!AL6 -> 1.2014485 | AM6: =IVCFlow!AM6-ArterialFlow!AM6 -> 0.95080278 | AN6: =IVCFlow!AN6-ArterialFlow!AN6 -> 1.0423222 | AO6: =IVCFlow!AO6-ArterialFlow!AO6 -> 1.0286089 | ... AQ6: =IVCFlow!AQ6-ArterialFlow!AQ6 -> 1.1104335 | AS6: =IVCFlow!AS6-ArterialFlow!AS6 -> 1.2004028 | AT6: =IVCFlow!AT6-ArterialFlow!AT6 -> 0.96458993 | AU6: =IVCFlow!AU6-ArterialFlow!AU6 -> 1.2976577 | AV6: =IVCFlow!AV6-ArterialFlow!AV6 -> 1.0932666 | AW6: =IVCFlow!AW6-ArterialFlow!AW6 -> 1.1565805 | AY6: =IVCFlow!AY6-ArterialFlow!AY6 -> 1.2677806 | AZ6: =IVCFlow!AZ6-ArterialFlow!AZ6 -> 1.1651238 | BA6: =IVCFlow!BA6-ArterialFlow!BA6 -> 1.0232417 | BB6: =IVCFlow!BB6-ArterialFlow!BB6 -> 1.055586 | BC6: =IVCFlow!BC6-ArterialFlow!BC6 -> 1.2785194 | BD6: =IVCFlow!BD6-ArterialFlow!BD6 -> 0.97918844 | BE6: =IVCFlow!BE6-ArterialFlow!BE6 -> 1.0479021 | BF6: =IVCFlow!BF6-ArterialFlow!BF6 -> 1.1291748 | ... BI6: =IVCFlow!BI6-ArterialFlow!BI6 -> 1.4079333 | BL6: =IVCFlow!BL6-ArterialFlow!BL6 -> 1.0899528 | BM6: =IVCFlow!BM6-ArterialFlow!BM6 -> 1.2004028 | BN6: =IVCFlow!BN6-ArterialFlow!BN6 -> 1.1792025 | BO6: =IVCFlow!BO6-ArterialFlow!BO6 -> 1.0634222 | BP6: =IVCFlow!BP6-ArterialFlow!BP6 -> 1.1818195 | BQ6: =IVCFlow!BQ6-ArterialFlow!BQ6 -> 1.0444833 | BR6: =IVCFlow!BR6-ArterialFlow!BR6 -> 1.2314861 | BT6: =IVCFlow!BT6-ArterialFlow!BT6 -> 1.2666834 | BU6: =IVCFlow!BU6-ArterialFlow!BU6 -> 1.0820028 | BV6: =IVCFlow!BV6-ArterialFlow!BV6 -> 1.1905944 | BW6: =IVCFlow!BW6-ArterialFlow!BW6 -> 1.0541956 | BX6: =IVCFlow!BX6-ArterialFlow!BX6 -> 1.0007917 | BY6: =IVCFlow!BY6-ArterialFlow!BY6 -> 1.2116681 | BZ6: 1.5703861 | CA6: =IVCFlow!CA6-ArterialFlow!CA6 -> 0.98773611 | CB6: =IVCFlow!CB6-ArterialFlow!CB6 -> 1.02469 | CC6: =IVCFlow!CC6-ArterialFlow!CC6 -> 1.0284714 | CD6: =IVCFlow!CD6-ArterialFlow!CD6 -> 1.1796193 | CE6: =IVCFlow!CE6-ArterialFlow!CE6 -> 1.1259305 | CF6: =IVCFlow!CF6-ArterialFlow!CF6 -> 1.2259972 | CG6: =IVCFlow!CG6-ArterialFlow!CG6 -> 1.2976632 | CH6: =IVCFlow!CH6-ArterialFlow!CH6 -> 1.26778 | ... CJ6: =IVCFlow!CJ6-ArterialFlow!CJ6 -> 1.0232148 | CK6: End of Perfusion | CL6: =AVERAGE(B6,C6,D20,E6,F13,G13,H9,I16,J8,K21,L13,M14,N15,O12,P20,Q12,R16,S9,T12,U12,V12,W11,X7,Y8,Z6,AB8,AD11,AC7,AE8,AF10,AG5,AH8,AI9,AJ11,AK10,AL9,AM13,AN11,AO11,AP7,AQ7,AR6,AS9,AT13,AU10,AV10,AW22,AY10,AZ10,BA12,BB17,BC8,BD7,BE17,BF11,BG7,BH19,BI10,BJ5,BK5,BL9,BM9,BN14,BO12,BP8,BQ10,BR8,BS5,BT9,BU11,BV11,BW13,BX10,BY17,BZ9,CA21,CB12,CC12,CD12,CE15,CF8,CG10,CH10,CI11,CJ12) -> 1.0079501 | CM6: =STDEV(B6,C6,D20,E6,F13,G13,H9,I16,J8,K21,L13,M14,N15,O12,P20,Q12,R16,S9,T12,U12,V12,W11,X7,Y8,Z6,AB8,AD11,AC7,AE8,AF10,AG5,AH8,AI9,AJ11,AK10,AL9,AM13,AN11,AO11,AP7,AQ7,AR6,AS9,AT13,AU10,AV10,AW22,AY10,AZ10,BA12,BB17,BC8,BD7,BE17,BF11,BG7,BH19,BI10,BJ5,BK5,BL9,BM9,BN14,BO12,BP8,BQ10,BR8,BS5,BT9,BU11,BV11,BW13,BX10,BY17,BZ9,CA21,CB12,CC12,CD12,CE15,CF8,CG10,CH10,CI11,CJ12) -> 0.16048239 | CN6: =CM6/SQRT(COUNT(B6:CJ6)) -> 0.017942477
A7: 4 | D7: =IVCFlow!D7-ArterialFlow!D7 -> 0.9145985 | F7: =IVCFlow!F7-ArterialFlow!F7 -> 1.0857333 | G7: =IVCFlow!G7-ArterialFlow!G7 -> 1.0857333 | H7: =IVCFlow!H7-ArterialFlow!H7 -> 1.1594795 | I7: =IVCFlow!I7-ArterialFlow!I7 -> 1.0317288 | J7: =IVCFlow!J7-ArterialFlow!J7 -> 1.0176278 | K7: =IVCFlow!K7-ArterialFlow!K7 -> 0.89813137 | L7: =IVCFlow!L7-ArterialFlow!L7 -> 0.9405032 | M7: =IVCFlow!M7-ArterialFlow!M7 -> 0.93400723 | ... Y7: =IVCFlow!Y7-ArterialFlow!Y7 -> 1.0349055 | AB7: =IVCFlow!AB7-ArterialFlow!AB7 -> 1.2266546 | AC7: =IVCFlow!AC7-ArterialFlow!AC7 -> 1.1625797 | AD7: =IVCFlow!AD7-ArterialFlow!AD7 -> 1.1533118 | AE7: =IVCFlow!AE7-ArterialFlow!AE7 -> 1.1646955 | AF7: =IVCFlow!AF7-ArterialFlow!AF7 -> 0.94943795 | AH7: =IVCFlow!AH7-ArterialFlow!AH7 -> 1.2327467 | AI7: =IVCFlow!AI7-ArterialFlow!AI7 -> 1.2476639 | AJ7: =IVCFlow!AJ7-ArterialFlow!AJ7 -> 1.1442818 | AK7: =IVCFlow!AK7-ArterialFlow!AK7 -> 0.99019478 | AL7: =IVCFlow!AL7-ArterialFlow!AL7 -> 1.2145895 | AM7: =IVCFlow!AM7-ArterialFlow!AM7 -> 0.90431389 | AN7: =IVCFlow!AN7-ArterialFlow!AN7 -> 1.1800222 | AO7: =IVCFlow!AO7-ArterialFlow!AO7 -> 1.0253529 | ... AQ7: =IVCFlow!AQ7-ArterialFlow!AQ7 -> 1.0684801 | AS7: =IVCFlow!AS7-ArterialFlow!AS7 -> 1.2657334 | AT7: =IVCFlow!AT7-ArterialFlow!AT7 -> 0.9691961 | AU7: =IVCFlow!AU7-ArterialFlow!AU7 -> 1.2637473 | AV7: =IVCFlow!AV7-ArterialFlow!AV7 -> 0.99671857 | AW7: =IVCFlow!AW7-ArterialFlow!AW7 -> 1.1538365 | AY7: =IVCFlow!AY7-ArterialFlow!AY7 -> 1.2629778 | AZ7: =IVCFlow!AZ7-ArterialFlow!AZ7 -> 1.1495993 | BA7: =IVCFlow!BA7-ArterialFlow!BA7 -> 1.0053639 | BB7: =IVCFlow!BB7-ArterialFlow!BB7 -> 1.0623372 | BC7: =IVCFlow!BC7-ArterialFlow!BC7 -> 1.259875 | BE7: =IVCFlow!BE7-ArterialFlow!BE7 -> 1.0333523 | BF7: =IVCFlow!BF7-ArterialFlow!BF7 -> 0.97786429 | BH7: =IVCFlow!BH7-ArterialFlow!BH7 -> 1.3002722 | BI7: =IVCFlow!BI7-ArterialFlow!BI7 -> 1.4257444 | BL7: =IVCFlow!BL7-ArterialFlow!BL7 -> 1.0919528 | BM7: =IVCFlow!BM7-ArterialFlow!BM7 -> 1.2657334 | BN7: =IVCFlow!BN7-ArterialFlow!BN7 -> 1.1733889 | BO7: =IVCFlow!BO7-ArterialFlow!BO7 -> 0.96536111 | BP7: =IVCFlow!BP7-ArterialFlow!BP7 -> 1.1646972 | BQ7: =IVCFlow!BQ7-ArterialFlow!BQ7 -> 0.94933315 | BR7: =IVCFlow!BR7-ArterialFlow!BR7 -> 1.2327889 | BT7: =IVCFlow!BT7-ArterialFlow!BT7 -> 1.2476639 | BU7: =IVCFlow!BU7-ArterialFlow!BU7 -> 1.0848194 | BV7: =IVCFlow!BV7-ArterialFlow!BV7 -> 1.1442778 | BW7: =IVCFlow!BW7-ArterialFlow!BW7 -> 1.0335982 | BX7: =IVCFlow!BX7-ArterialFlow!BX7 -> 0.99019446 | BY7: =IVCFlow!BY7-ArterialFlow!BY7 -> 1.2077445 | BZ7: 1.584975 | CA7: =IVCFlow!CA7-ArterialFlow!CA7 -> 0.95420951 | CB7: =IVCFlow!CB7-ArterialFlow!CB7 -> 1.0229425 | CC7: =IVCFlow!CC7-ArterialFlow!CC7 -> 1.0257028 | CD7: =IVCFlow!CD7-ArterialFlow!CD7 -> 1.1985361 | CE7: =IVCFlow!CE7-ArterialFlow!CE7 -> 1.1252222 | CF7: =IVCFlow!CF7-ArterialFlow!CF7 -> 1.2040706 | CG7: =IVCFlow!CG7-ArterialFlow!CG7 -> 1.2637511 | CH7: =IVCFlow!CH7-ArterialFlow!CH7 -> 1.2629778 | ... CJ7: =IVCFlow!CJ7-ArterialFlow!CJ7 -> 1.0053639
A8: 5 | D8: =IVCFlow!D8-ArterialFlow!D8 -> 0.90895527 | F8: =IVCFlow!F8-ArterialFlow!F8 -> 1.0391498 | G8: =IVCFlow!G8-ArterialFlow!G8 -> 1.0391498 | H8: =IVCFlow!H8-ArterialFlow!H8 -> 1.1530495 | I8: =IVCFlow!I8-ArterialFlow!I8 -> 1.0163558 | J8: =IVCFlow!J8-ArterialFlow!J8 -> 0.69461539 | K8: =IVCFlow!K8-ArterialFlow!K8 -> 0.90257173 | L8: =IVCFlow!L8-ArterialFlow!L8 -> 0.93264943 | M8: =IVCFlow!M8-ArterialFlow!M8 -> 0.90063073 | ... W8: =IVCFlow!W8-ArterialFlow!W8 -> 1.17949 | Y8: =IVCFlow!Y8-ArterialFlow!Y8 -> 1.1114626 | AB8: =IVCFlow!AB8-ArterialFlow!AB8 -> 1.2323994 | AD8: =IVCFlow!AD8-ArterialFlow!AD8 -> 1.145476 | AE8: =IVCFlow!AE8-ArterialFlow!AE8 -> 1.1182196 | AF8: =IVCFlow!AF8-ArterialFlow!AF8 -> 0.95175947 | AH8: =IVCFlow!AH8-ArterialFlow!AH8 -> 1.0783 | AI8: =IVCFlow!AI8-ArterialFlow!AI8 -> 1.2532028 | AJ8: =IVCFlow!AJ8-ArterialFlow!AJ8 -> 1.1120395 | AK8: =IVCFlow!AK8-ArterialFlow!AK8 -> 0.99987997 | AL8: =IVCFlow!AL8-ArterialFlow!AL8 -> 1.1876794 | AM8: =IVCFlow!AM8-ArterialFlow!AM8 -> 0.9001139 | AN8: =IVCFlow!AN8-ArterialFlow!AN8 -> 1.1689056 | AO8: =IVCFlow!AO8-ArterialFlow!AO8 -> 1.0431125 | AQ8: =IVCFlow!AQ8-ArterialFlow!AQ8 -> 0.90706522 | AS8: =IVCFlow!AS8-ArterialFlow!AS8 -> 1.1034028 | AT8: =IVCFlow!AT8-ArterialFlow!AT8 -> 0.95516944 | AU8: =IVCFlow!AU8-ArterialFlow!AU8 -> 1.2509175 | AV8: =IVCFlow!AV8-ArterialFlow!AV8 -> 1.0252154 | AW8: =IVCFlow!AW8-ArterialFlow!AW8 -> 1.1275326 | AY8: =IVCFlow!AY8-ArterialFlow!AY8 -> 1.26325 | AZ8: =IVCFlow!AZ8-ArterialFlow!AZ8 -> 1.210181 | BA8: =IVCFlow!BA8-ArterialFlow!BA8 -> 1.0665027 | BB8: =IVCFlow!BB8-ArterialFlow!BB8 -> 1.0562136 | BE8: =IVCFlow!BE8-ArterialFlow!BE8 -> 1.0455469 | BF8: =IVCFlow!BF8-ArterialFlow!BF8 -> 1.1305644 | BH8: =IVCFlow!BH8-ArterialFlow!BH8 -> 1.2964778 | BI8: =IVCFlow!BI8-ArterialFlow!BI8 -> 1.4102111 | BL8: =IVCFlow!BL8-ArterialFlow!BL8 -> 0.81592222 | BM8: =IVCFlow!BM8-ArterialFlow!BM8 -> 1.1034028 | BN8: =IVCFlow!BN8-ArterialFlow!BN8 -> 1.1841326 | BO8: =IVCFlow!BO8-ArterialFlow!BO8 -> 0.94958056 | BP8: =IVCFlow!BP8-ArterialFlow!BP8 -> 1.1182295 | BQ8: =IVCFlow!BQ8-ArterialFlow!BQ8 -> 0.95174722 | BR8: =IVCFlow!BR8-ArterialFlow!BR8 -> 1.0783 | BT8: =IVCFlow!BT8-ArterialFlow!BT8 -> 1.2532028 | BU8: =IVCFlow!BU8-ArterialFlow!BU8 -> 1.0753417 | BV8: =IVCFlow!BV8-ArterialFlow!BV8 -> 1.1120389 | BW8: =IVCFlow!BW8-ArterialFlow!BW8 -> 1.0653084 | BX8: =IVCFlow!BX8-ArterialFlow!BX8 -> 0.99986664 | BY8: =IVCFlow!BY8-ArterialFlow!BY8 -> 1.1619194 | BZ8: 1.5527444 | CA8: =IVCFlow!CA8-ArterialFlow!CA8 -> 1.0107305 | CB8: =IVCFlow!CB8-ArterialFlow!CB8 -> 1.0100028 | CC8: =IVCFlow!CC8-ArterialFlow!CC8 -> 1.0441528 | CD8: =IVCFlow!CD8-ArterialFlow!CD8 -> 1.1588389 | CE8: =IVCFlow!CE8-ArterialFlow!CE8 -> 1.0766102 | CF8: =IVCFlow!CF8-ArterialFlow!CF8 -> 1.175021 | CG8: =IVCFlow!CG8-ArterialFlow!CG8 -> 1.2509084 | CH8: =IVCFlow!CH8-ArterialFlow!CH8 -> 1.26325 | ... CJ8: =IVCFlow!CJ8-ArterialFlow!CJ8 -> 1.0665027
A9: 6 | D9: =IVCFlow!D9-ArterialFlow!D9 -> 0.80022675 | F9: =IVCFlow!F9-ArterialFlow!F9 -> 1.0829767 | G9: =IVCFlow!G9-ArterialFlow!G9 -> 1.0829767 | H9: =IVCFlow!H9-ArterialFlow!H9 -> 0.95233775 | I9: =IVCFlow!I9-ArterialFlow!I9 -> 0.99834586 | K9: =IVCFlow!K9-ArterialFlow!K9 -> 0.89462778 | L9: =IVCFlow!L9-ArterialFlow!L9 -> 0.90982735 | M9: =IVCFlow!M9-ArterialFlow!M9 -> 0.89916296 | N9: =IVCFlow!N9-ArterialFlow!N9 -> 0.83110802 | O9: =IVCFlow!O9-ArterialFlow!O9 -> 1.0885278 | P9: =IVCFlow!P9-ArterialFlow!P9 -> 1.0942139 | Q9: =IVCFlow!Q9-ArterialFlow!Q9 -> 1.0771603 | R9: =IVCFlow!R9-ArterialFlow!R9 -> 0.92877364 | ... W9: =IVCFlow!W9-ArterialFlow!W9 -> 1.1643064 | AD9: =IVCFlow!AD9-ArterialFlow!AD9 -> 1.0954728 | AF9: =IVCFlow!AF9-ArterialFlow!AF9 -> 0.94559789 | AI9: =IVCFlow!AI9-ArterialFlow!AI9 -> 1.22548 | AJ9: =IVCFlow!AJ9-ArterialFlow!AJ9 -> 1.0795549 | AK9: =IVCFlow!AK9-ArterialFlow!AK9 -> 0.99525478 | AL9: =IVCFlow!AL9-ArterialFlow!AL9 -> 1.1595704 | AM9: =IVCFlow!AM9-ArterialFlow!AM9 -> 0.84453193 | AN9: =IVCFlow!AN9-ArterialFlow!AN9 -> 1.1712306 | AO9: =IVCFlow!AO9-ArterialFlow!AO9 -> 1.0652848 | AS9: =IVCFlow!AS9-ArterialFlow!AS9 -> 0.71183452 | AT9: =IVCFlow!AT9-ArterialFlow!AT9 -> 0.9587771 | AU9: =IVCFlow!AU9-ArterialFlow!AU9 -> 1.2330442 | AV9: =IVCFlow!AV9-ArterialFlow!AV9 -> 1.0291717 | AW9: =IVCFlow!AW9-ArterialFlow!AW9 -> 1.110367 | AY9: =IVCFlow!AY9-ArterialFlow!AY9 -> 1.26435 | AZ9: =IVCFlow!AZ9-ArterialFlow!AZ9 -> 1.1493931 | BA9: =IVCFlow!BA9-ArterialFlow!BA9 -> 1.0396472 | BB9: =IVCFlow!BB9-ArterialFlow!BB9 -> 1.0878944 | BE9: =IVCFlow!BE9-ArterialFlow!BE9 -> 1.0475468 | BF9: =IVCFlow!BF9-ArterialFlow!BF9 -> 1.1165815 | BH9: =IVCFlow!BH9-ArterialFlow!BH9 -> 1.2899889 | BI9: =IVCFlow!BI9-ArterialFlow!BI9 -> 1.4202587 | BN9: =IVCFlow!BN9-ArterialFlow!BN9 -> 1.1735186 | BO9: =IVCFlow!BO9-ArterialFlow!BO9 -> 0.93726667 | BQ9: =IVCFlow!BQ9-ArterialFlow!BQ9 -> 0.94521389 | BT9: =IVCFlow!BT9-ArterialFlow!BT9 -> 1.2254764 | BU9: =IVCFlow!BU9-ArterialFlow!BU9 -> 1.0812528 | BV9: =IVCFlow!BV9-ArterialFlow!BV9 -> 1.0795577 | BW9: =IVCFlow!BW9-ArterialFlow!BW9 -> 1.0317417 | BX9: =IVCFlow!BX9-ArterialFlow!BX9 -> 0.99527776 | BY9: =IVCFlow!BY9-ArterialFlow!BY9 -> 1.1581161 | BZ9: 1.5190011 | CA9: =IVCFlow!CA9-ArterialFlow!CA9 -> 1.009475 | CB9: =IVCFlow!CB9-ArterialFlow!CB9 -> 0.98466777 | CC9: =IVCFlow!CC9-ArterialFlow!CC9 -> 1.0652944 | CD9: =IVCFlow!CD9-ArterialFlow!CD9 -> 1.0691556 | CE9: =IVCFlow!CE9-ArterialFlow!CE9 -> 1.0386722 | CG9: =IVCFlow!CG9-ArterialFlow!CG9 -> 1.23305 | CH9: =IVCFlow!CH9-ArterialFlow!CH9 -> 1.26435 | CI9: =IVCFlow!CI9-ArterialFlow!CI9 -> 1.1494491 | CJ9: =IVCFlow!CJ9-ArterialFlow!CJ9 -> 1.0396472
A10: 7 | D10: =IVCFlow!D10-ArterialFlow!D10 -> 1.0913674 | F10: =IVCFlow!F10-ArterialFlow!F10 -> 1.0761972 | G10: =IVCFlow!G10-ArterialFlow!G10 -> 1.0761972 | I10: =IVCFlow!I10-ArterialFlow!I10 -> 1.011767 | K10: =IVCFlow!K10-ArterialFlow!K10 -> 0.88763333 | L10: =IVCFlow!L10-ArterialFlow!L10 -> 0.92735639 | M10: =IVCFlow!M10-ArterialFlow!M10 -> 0.91183537 | N10: =IVCFlow!N10-ArterialFlow!N10 -> 0.92939276 | O10: =IVCFlow!O10-ArterialFlow!O10 -> 1.0762949 | P10: =IVCFlow!P10-ArterialFlow!P10 -> 1.0477417 | Q10: =IVCFlow!Q10-ArterialFlow!Q10 -> 1.0354049 | R10: =IVCFlow!R10-ArterialFlow!R10 -> 0.91073611 | T10: =IVCFlow!T10-ArterialFlow!T10 -> 1.0562139 | U10: =IVCFlow!U10-ArterialFlow!U10 -> 1.0228933 | V10: =IVCFlow!V10-ArterialFlow!V10 -> 0.72971944 | W10: =IVCFlow!W10-ArterialFlow!W10 -> 1.1691897 | AD10: =IVCFlow!AD10-ArterialFlow!AD10 -> 1.0957686 | AF10: =IVCFlow!AF10-ArterialFlow!AF10 -> 0.8244958 | AJ10: =IVCFlow!AJ10-ArterialFlow!AJ10 -> 1.053797 | AK10: =IVCFlow!AK10-ArterialFlow!AK10 -> 0.95359849 | AM10: =IVCFlow!AM10-ArterialFlow!AM10 -> 0.85964424 | AN10: =IVCFlow!AN10-ArterialFlow!AN10 -> 1.1666203 | AO10: =IVCFlow!AO10-ArterialFlow!AO10 -> 1.1010808 | AT10: =IVCFlow!AT10-ArterialFlow!AT10 -> 0.95179494 | AU10: =IVCFlow!AU10-ArterialFlow!AU10 -> 1.2275817 | AV10: =IVCFlow!AV10-ArterialFlow!AV10 -> 1.0527339 | AW10: =IVCFlow!AW10-ArterialFlow!AW10 -> 1.1032749 | AY10: =IVCFlow!AY10-ArterialFlow!AY10 -> 0.82638661 | AZ10: =IVCFlow!AZ10-ArterialFlow!AZ10 -> 0.85831246 | BA10: =IVCFlow!BA10-ArterialFlow!BA10 -> 1.0392164 | BB10: =IVCFlow!BB10-ArterialFlow!BB10 -> 1.1093805 | BE10: =IVCFlow!BE10-ArterialFlow!BE10 -> 1.0201679 | BF10: =IVCFlow!BF10-ArterialFlow!BF10 -> 1.1178953 | BH10: =IVCFlow!BH10-ArterialFlow!BH10 -> 1.2917278 | BN10: =IVCFlow!BN10-ArterialFlow!BN10 -> 1.1736194 | BO10: =IVCFlow!BO10-ArterialFlow!BO10 -> 0.93843611 | BQ10: =IVCFlow!BQ10-ArterialFlow!BQ10 -> 0.82108786 | BU10: =IVCFlow!BU10-ArterialFlow!BU10 -> 1.1198806 | BV10: =IVCFlow!BV10-ArterialFlow!BV10 -> 1.0537566 | BW10: =IVCFlow!BW10-ArterialFlow!BW10 -> 1.0325139 | BX10: =IVCFlow!BX10-ArterialFlow!BX10 -> 0.95428705 | BY10: =IVCFlow!BY10-ArterialFlow!BY10 -> 1.1647611 | CA10: =IVCFlow!CA10-ArterialFlow!CA10 -> 1.0116504 | CB10: =IVCFlow!CB10-ArterialFlow!CB10 -> 0.93589101 | CC10: =IVCFlow!CC10-ArterialFlow!CC10 -> 1.101075 | CD10: =IVCFlow!CD10-ArterialFlow!CD10 -> 1.0719844 | CE10: =IVCFlow!CE10-ArterialFlow!CE10 -> 1.0329167 | CG10: =IVCFlow!CG10-ArterialFlow!CG10 -> 1.2276616 | CI10: =IVCFlow!CI10-ArterialFlow!CI10 -> 0.85794659 | CJ10: =IVCFlow!CJ10-ArterialFlow!CJ10 -> 1.0392134
A11: 8 | D11: =IVCFlow!D11-ArterialFlow!D11 -> 1.1017899 | F11: =IVCFlow!F11-ArterialFlow!F11 -> 1.0820805 | G11: =IVCFlow!G11-ArterialFlow!G11 -> 1.0820805 | I11: =IVCFlow!I11-ArterialFlow!I11 -> 0.99091618 | K11: =IVCFlow!K11-ArterialFlow!K11 -> 0.88782222 | L11: =IVCFlow!L11-ArterialFlow!L11 -> 0.92190993 | M11: =IVCFlow!M11-ArterialFlow!M11 -> 0.91197442 | N11: =IVCFlow!N11-ArterialFlow!N11 -> 0.94162253 | O11: =IVCFlow!O11-ArterialFlow!O11 -> 1.0628385 | P11: =IVCFlow!P11-ArterialFlow!P11 -> 1.0342301 | Q11: =IVCFlow!Q11-ArterialFlow!Q11 -> 1.0906365 | R11: =IVCFlow!R11-ArterialFlow!R11 -> 0.89975819 | T11: =IVCFlow!T11-ArterialFlow!T11 -> 1.102175 | U11: =IVCFlow!U11-ArterialFlow!U11 -> 0.97843444 | V11: =IVCFlow!V11-ArterialFlow!V11 -> 0.72685277 | W11: =IVCFlow!W11-ArterialFlow!W11 -> 1.1791291 | AD11: =IVCFlow!AD11-ArterialFlow!AD11 -> 1.1244106 | AJ11: =IVCFlow!AJ11-ArterialFlow!AJ11 -> 0.99342697 | AM11: =IVCFlow!AM11-ArterialFlow!AM11 -> 0.87964426 | AN11: =IVCFlow!AN11-ArterialFlow!AN11 -> 1.1691581 | AO11: =IVCFlow!AO11-ArterialFlow!AO11 -> 1.1167805 | AT11: =IVCFlow!AT11-ArterialFlow!AT11 -> 0.95883792 | AW11: =IVCFlow!AW11-ArterialFlow!AW11 -> 1.064172 | BA11: =IVCFlow!BA11-ArterialFlow!BA11 -> 0.78649386 | BB11: =IVCFlow!BB11-ArterialFlow!BB11 -> 1.1103556 | BE11: =IVCFlow!BE11-ArterialFlow!BE11 -> 1.0266951 | BH11: =IVCFlow!BH11-ArterialFlow!BH11 -> 1.2935834 | BN11: =IVCFlow!BN11-ArterialFlow!BN11 -> 1.1631731 | BO11: =IVCFlow!BO11-ArterialFlow!BO11 -> 0.95358611 | BU11: =IVCFlow!BU11-ArterialFlow!BU11 -> 1.0734276 | BV11: =IVCFlow!BV11-ArterialFlow!BV11 -> 0.99342697 | BW11: =IVCFlow!BW11-ArterialFlow!BW11 -> 1.0184385 | BY11: =IVCFlow!BY11-ArterialFlow!BY11 -> 1.1533528 | CA11: =IVCFlow!CA11-ArterialFlow!CA11 -> 1.0140355 | CB11: =IVCFlow!CB11-ArterialFlow!CB11 -> 0.94051124 | CC11: =IVCFlow!CC11-ArterialFlow!CC11 -> 1.1167805 | CD11: =IVCFlow!CD11-ArterialFlow!CD11 -> 1.1236361 | CE11: =IVCFlow!CE11-ArterialFlow!CE11 -> 1.0384801 | CJ11: =IVCFlow!CJ11-ArterialFlow!CJ11 -> 0.78644901
A12: 9 | D12: =IVCFlow!D12-ArterialFlow!D12 -> 1.1030934 | F12: =IVCFlow!F12-ArterialFlow!F12 -> 1.0909088 | G12: =IVCFlow!G12-ArterialFlow!G12 -> 1.0909088 | I12: =IVCFlow!I12-ArterialFlow!I12 -> 1.0038123 | K12: =IVCFlow!K12-ArterialFlow!K12 -> 0.87683482 | L12: =IVCFlow!L12-ArterialFlow!L12 -> 0.95276897 | M12: =IVCFlow!M12-ArterialFlow!M12 -> 0.90571151 | N12: =IVCFlow!N12-ArterialFlow!N12 -> 0.94958218 | O12: =IVCFlow!O12-ArterialFlow!O12 -> 1.055327 | P12: =IVCFlow!P12-ArterialFlow!P12 -> 1.0548097 | Q12: =IVCFlow!Q12-ArterialFlow!Q12 -> 1.0564657 | R12: =IVCFlow!R12-ArterialFlow!R12 -> 0.88123402 | T12: =IVCFlow!T12-ArterialFlow!T12 -> 0.93864942 | U12: =IVCFlow!U12-ArterialFlow!U12 -> 0.87083333 | V12: =IVCFlow!V12-ArterialFlow!V12 -> 0.72498747 | AM12: =IVCFlow!AM12-ArterialFlow!AM12 -> 0.86591428 | AN12: =IVCFlow!AN12-ArterialFlow!AN12 -> 0.83940676 | AO12: =IVCFlow!AO12-ArterialFlow!AO12 -> 0.51952363 | AT12: =IVCFlow!AT12-ArterialFlow!AT12 -> 0.95170237 | AW12: =IVCFlow!AW12-ArterialFlow!AW12 -> 1.0560779 | BB12: =IVCFlow!BB12-ArterialFlow!BB12 -> 1.1312587 | BE12: =IVCFlow!BE12-ArterialFlow!BE12 -> 1.032964 | BH12: =IVCFlow!BH12-ArterialFlow!BH12 -> 1.2962278 | BN12: =IVCFlow!BN12-ArterialFlow!BN12 -> 1.1690331 | BO12: =IVCFlow!BO12-ArterialFlow!BO12 -> 0.91983813 | BW12: =IVCFlow!BW12-ArterialFlow!BW12 -> 0.99344821 | BY12: =IVCFlow!BY12-ArterialFlow!BY12 -> 1.1399195 | CA12: =IVCFlow!CA12-ArterialFlow!CA12 -> 1.0281472 | CB12: =IVCFlow!CB12-ArterialFlow!CB12 -> 0.89727047 | CD12: =IVCFlow!CD12-ArterialFlow!CD12 -> 1.0964754 | CE12: =IVCFlow!CE12-ArterialFlow!CE12 -> 1.0346361
A13: 10 | D13: =IVCFlow!D13-ArterialFlow!D13 -> 1.1234908 | F13: =IVCFlow!F13-ArterialFlow!F13 -> 1.0104173 | G13: =IVCFlow!G13-ArterialFlow!G13 -> 1.0104173 | I13: =IVCFlow!I13-ArterialFlow!I13 -> 0.9901727 | K13: =IVCFlow!K13-ArterialFlow!K13 -> 0.9185496 | L13: =IVCFlow!L13-ArterialFlow!L13 -> 0.88825843 | M13: =IVCFlow!M13-ArterialFlow!M13 -> 0.90272298 | N13: =IVCFlow!N13-ArterialFlow!N13 -> 0.93009746 | P13: =IVCFlow!P13-ArterialFlow!P13 -> 1.0816639 | R13: =IVCFlow!R13-ArterialFlow!R13 -> 0.90551321 | AM13: =IVCFlow!AM13-ArterialFlow!AM13 -> 0.88947336 | AT13: =IVCFlow!AT13-ArterialFlow!AT13 -> 0.95210162 | AW13: =IVCFlow!AW13-ArterialFlow!AW13 -> 1.0776508 | BB13: =IVCFlow!BB13-ArterialFlow!BB13 -> 1.1301805 | BE13: =IVCFlow!BE13-ArterialFlow!BE13 -> 1.0433845 | BH13: =IVCFlow!BH13-ArterialFlow!BH13 -> 1.3005278 | BN13: =IVCFlow!BN13-ArterialFlow!BN13 -> 1.1415671 | BY13: =IVCFlow!BY13-ArterialFlow!BY13 -> 1.1173667 | CA13: =IVCFlow!CA13-ArterialFlow!CA13 -> 1.0265639 | CE13: =IVCFlow!CE13-ArterialFlow!CE13 -> 1.0424361 | CS13: =
A14: 11 | D14: =IVCFlow!D14-ArterialFlow!D14 -> 1.1794939 | I14: =IVCFlow!I14-ArterialFlow!I14 -> 0.99598102 | K14: =IVCFlow!K14-ArterialFlow!K14 -> 0.922409 | M14: =IVCFlow!M14-ArterialFlow!M14 -> 0.66706673 | N14: =IVCFlow!N14-ArterialFlow!N14 -> 0.86912231 | P14: =IVCFlow!P14-ArterialFlow!P14 -> 1.0818318 | R14: =IVCFlow!R14-ArterialFlow!R14 -> 0.9093856 | AW14: =IVCFlow!AW14-ArterialFlow!AW14 -> 1.0796634 | BB14: =IVCFlow!BB14-ArterialFlow!BB14 -> 1.1319667 | BE14: =IVCFlow!BE14-ArterialFlow!BE14 -> 1.0387184 | BH14: =IVCFlow!BH14-ArterialFlow!BH14 -> 1.3016167 | BN14: =IVCFlow!BN14-ArterialFlow!BN14 -> 1.0934521 | BY14: =IVCFlow!BY14-ArterialFlow!BY14 -> 1.1187 | CA14: =IVCFlow!CA14-ArterialFlow!CA14 -> 1.05715 | CE14: =IVCFlow!CE14-ArterialFlow!CE14 -> 0.92862778
A15: 12 | D15: =IVCFlow!D15-ArterialFlow!D15 -> 1.2153196 | I15: =IVCFlow!I15-ArterialFlow!I15 -> 1.0262462 | K15: =IVCFlow!K15-ArterialFlow!K15 -> 0.93207615 | N15: =IVCFlow!N15-ArterialFlow!N15 -> 0.86515375 | P15: =IVCFlow!P15-ArterialFlow!P15 -> 1.0971905 | R15: =IVCFlow!R15-ArterialFlow!R15 -> 0.90071468 | AW15: =IVCFlow!AW15-ArterialFlow!AW15 -> 1.071757 | BB15: =IVCFlow!BB15-ArterialFlow!BB15 -> 1.1337389 | BE15: =IVCFlow!BE15-ArterialFlow!BE15 -> 1.0490796 | BH15: =IVCFlow!BH15-ArterialFlow!BH15 -> 1.30085 | BY15: =IVCFlow!BY15-ArterialFlow!BY15 -> 1.1174639 | CA15: =IVCFlow!CA15-ArterialFlow!CA15 -> 1.0466889
A16: 13 | D16: =IVCFlow!D16-ArterialFlow!D16 -> 1.2373291 | K16: =IVCFlow!K16-ArterialFlow!K16 -> 0.95392549 | P16: =IVCFlow!P16-ArterialFlow!P16 -> 1.0877914 | R16: =IVCFlow!R16-ArterialFlow!R16 -> 0.72366894 | AW16: =IVCFlow!AW16-ArterialFlow!AW16 -> 1.0580261 | BB16: =IVCFlow!BB16-ArterialFlow!BB16 -> 1.0152474 | BE16: =IVCFlow!BE16-ArterialFlow!BE16 -> 1.0502824 | BH16: =IVCFlow!BH16-ArterialFlow!BH16 -> 1.301574 | BY16: =IVCFlow!BY16-ArterialFlow!BY16 -> 1.1208139 | CA16: =IVCFlow!CA16-ArterialFlow!CA16 -> 1.0316199
A17: 14 | D17: =IVCFlow!D17-ArterialFlow!D17 -> 1.2407675 | K17: =IVCFlow!K17-ArterialFlow!K17 -> 0.92560813 | P17: =IVCFlow!P17-ArterialFlow!P17 -> 1.0714178 | AW17: =IVCFlow!AW17-ArterialFlow!AW17 -> 1.0529433 | BE17: =IVCFlow!BE17-ArterialFlow!BE17 -> 0.91405385 | BH17: =IVCFlow!BH17-ArterialFlow!BH17 -> 0.62457804 | BY17: =IVCFlow!BY17-ArterialFlow!BY17 -> 1.0450528 | CA17: =IVCFlow!CA17-ArterialFlow!CA17 -> 1.0410695
A18: 15 | D18: =IVCFlow!D18-ArterialFlow!D18 -> 1.2435659 | K18: =IVCFlow!K18-ArterialFlow!K18 -> 0.93515042 | P18: =IVCFlow!P18-ArterialFlow!P18 -> 1.0723888 | AW18: =IVCFlow!AW18-ArterialFlow!AW18 -> 1.0506311 | BH18: =IVCFlow!BH18-ArterialFlow!BH18 -> 0.83061631 | CA18: =IVCFlow!CA18-ArterialFlow!CA18 -> 1.0462889
A19: 16 | D19: =IVCFlow!D19-ArterialFlow!D19 -> 1.2524492 | K19: =IVCFlow!K19-ArterialFlow!K19 -> 0.95726715 | P19: =IVCFlow!P19-ArterialFlow!P19 -> 1.0748553 | AW19: =IVCFlow!AW19-ArterialFlow!AW19 -> 1.1073457 | BH19: =IVCFlow!BH19-ArterialFlow!BH19 -> 0.85932454 | CA19: =IVCFlow!CA19-ArterialFlow!CA19 -> 1.0638288
A20: 17 | D20: =IVCFlow!D20-ArterialFlow!D20 -> 1.0513924 | K20: =IVCFlow!K20-ArterialFlow!K20 -> 0.94085794 | P20: =IVCFlow!P20-ArterialFlow!P20 -> 0.86499456 | AW20: =IVCFlow!AW20-ArterialFlow!AW20 -> 1.0981963 | CA20: =IVCFlow!CA20-ArterialFlow!CA20 -> 0.98451944
A21: 18 | K21: =IVCFlow!K21-ArterialFlow!K21 -> 0.96414243 | AW21: =IVCFlow!AW21-ArterialFlow!AW21 -> 1.0905654 | CA21: =IVCFlow!CA21-ArterialFlow!CA21 -> 0.90679111
A22: 19 | AW22: =IVCFlow!AW22-ArterialFlow!AW22 -> 1.1054867
A23: 20
A24: 21
A25: 22
A26: 23
A27: 24
CM1048576: =STDEV(C1048576:CL1048576) -> #DIV/0!

Sheet Bile4TP
B1: Files
A2: Hour | B2: 1 | C2: 2 | D2: 3 | E2: 4 | F2: 5 | G2: 6 | H2: 7 | I2: 8 | J2: 9 | K2: 10 | L2: 11 | M2: 12 | N2: 13 | O2: 14 | P2: 15 | Q2: 16 | R2: 17 | S2: 18 | T2: 19 | U2: 20 | V2: 21 | W2: 22 | X2: 23 | Y2: 24 | Z2: 25 | AA2: 26 | AB2: 27 | AC2: 28 | AD2: 29 | AE2: 30 | AF2: 31 | AG2: 32 | AH2: 33 | AI2: 34 | AJ2: 35 | AK2: 36 | AL2: =AK2+1 -> 37 | AM2: =AL2+1 -> 38 | AN2: =AM2+1 -> 39 | AO2: =AN2+1 -> 40 | AP2: =AO2+1 -> 41 | AQ2: =AP2+1 -> 42 | AR2: =AQ2+1 -> 43 | AS2: =AR2+1 -> 44 | ... CJ2: =CI2+1 -> 87 | CK2: HOUR | CL2: MEAN | CM2: SDEV | CN2: STD ERROR
A3: 0 | B3: 0 | C3: 0 | D3: 0 | E3: 0 | F3: 0 | G3: 0 | H3: 0 | I3: 0 | J3: 0 | K3: 0 | L3: 0 | M3: 0 | N3: 0 | O3: 0 | P3: 0 | Q3: 0 | R3: 0 | S3: 0 | T3: 0 | U3: 0 | V3: 0 | W3: 0 | X3: 0 | Y3: 0 | Z3: 0 | AB3: 0 | AC3: 0 | AD3: 0 | AE3: 0 | AF3: 0 | AG3: 0 | AH3: 0 | AI3: 0 | AJ3: 0 | AK3: 0 | AL3: 0 | AM3: 0 | AN3: 0 | AO3: 0 | AP3: 0 | AQ3: 0 | AR3: 0 | AS3: 0 | AT3: 0 | AU3: 0 | AV3: 0 | AW3: 0 | AY3: 0 | AZ3: 0 | BA3: 0 | BB3: 0 | BC3: 0 | BD3: 0 | BE3: 0 | BF3: 0 | BG3: 0 | BH3: 0 | BI3: 0 | BJ3: 0 | BK3: 0 | BL3: 0 | BM3: 0 | BN3: 0 | BO3: 0 | BP3: 0 | BQ3: 0 | BR3: 0 | BS3: 0 | BT3: 0 | BU3: 0 | BV3: 0 | BW3: 0 | BX3: 0 | BY3: 0 | BZ3: 0 | CA3: 0 | CB3: 0 | CC3: 0 | CD3: 0 | CE3: 0 | CF3: 0 | CG3: 0 | CH3: 0 | CI3: 0 | CJ3: 0 | CK3: First Hour | CL3: =AVERAGE(B3:CJ3) -> 0 | CM3: =STDEV(B3:CJ3) -> 0 | CN3: =CM3/SQRT(COUNT(B3:CJ3)) -> 0
A4: 1 | B4: 7.6285874 | C4: 3.1982882 | D4: 0 | E4: 0 | F4: 0.26791277 | G4: 0.26791277 | H4: 0 | I4: 1.2745317 | J4: 3.4808333 | K4: 0 | L4: 0 | M4: 0 | N4: 1.623124 | O4: 0.54555586 | P4: 6.560189 | Q4: 3.4184555 | R4: 3.6039466 | S4: 0 | T4: 0 | U4: 0.19083333 | V4: 1.7688889 | W4: 0 | X4: 5.8814361 | Y4: 0 | Z4: 0.76055613 | AB4: 4.1380368 | AC4: 4.8654007 | AD4: 0 | AE4: 10.683889 | AF4: 0 | AG4: 6.4286906 | AH4: 0.14098999 | AI4: 5.2988889 | AJ4: 17.41057 | AK4: 0 | AL4: 2.5825675 | AM4: 0 | AN4: 0 | AO4: 0 | AP4: 0 | AQ4: 7.3947222 | AR4: 9.6427379 | AS4: 0 | AT4: 0 | AU4: 0 | AV4: 8.1645359 | AW4: 5.8952778 | AY4: 7.3213889 | AZ4: 4.4075619 | BA4: 0 | BB4: 0 | BC4: 0 | BD4: 15.423985 | BE4: 7.248608 | BF4: 6.5547831 | BG4: 0 | BH4: 0 | BI4: 0 | BJ4: 29.823562 | BK4: 7.9894444 | BL4: 0 | BM4: 0 | BN4: 0.37593776 | BO4: 0 | BP4: 10.683889 | BQ4: 0 | BR4: 0.14083333 | BS4: 6.43 | BT4: 5.2988889 | BU4: 1.855 | BV4: 17.415 | BW4: 0.70944444 | BX4: 0 | BY4: 20.0225 | BZ4: 2.5769444 | CA4: 9.5741667 | CB4: 6.7870448 | CC4: 0 | CD4: 0 | CE4: 0.80222222 | CF4: 0 | CG4: 0 | CH4: 7.3213889 | CI4: 4.4105556 | CJ4: 0 | CK4: Second Hour | CL4: =AVERAGE(B4:CJ4) -> 3.4857707 | CM4: =STDEV(B4:CJ4) -> 5.357867 | CN4: =CM4/SQRT(COUNT(B4:CJ4)) -> 0.58114227
A5: 2 | B5: 13.565544 | C5: 12.513384 | D5: 3.7526093 | E5: 1.4876355 | F5: 5.2205143 | G5: 5.2205143 | H5: 0 | I5: 8.4768673 | J5: 6.4461111 | K5: 6.7288889 | L5: 0 | M5: 0 | N5: 8.4697648 | O5: 2.9396843 | P5: 18.613889 | Q5: 6.9377778 | R5: 13.727222 | S5: 0 | T5: 0 | U5: 8.6986378 | V5: 9.2691667 | W5: 0 | X5: 12.944568 | Y5: 0 | Z5: 9.550172 | AB5: 12.825675 | AC5: 10.324531 | AD5: 0 | AE5: 21.478877 | AF5: 0 | AG5: 18.197868 | AH5: 1.4248402 | AI5: 11.934444 | AJ5: 41.268191 | AK5: 1.4407675 | AL5: 10.539082 | AM5: 0 | AN5: 0 | AO5: 0 | AP5: 0 | AQ5: 13.835278 | AR5: 15.966611 | AS5: 0 | AT5: 0 | AU5: 0.95496247 | AV5: 18.441324 | AW5: 10.458889 | AY5: 13.721944 | AZ5: 10.735482 | BA5: 2.1863889 | BB5: 0.053603876 | BC5: 0 | BD5: 48.122613 | BE5: 12.255444 | BF5: 25.225097 | BG5: 0 | BH5: 0 | BI5: 0 | BJ5: 54.968079 | BK5: 13.188347 | BL5: 0 | BM5: 0 | BN5: 3.9902778 | BO5: 0 | BP5: 21.478333 | BQ5: 0 | BR5: 1.425 | BS5: 18.197868 | BT5: 11.934444 | BU5: 12.455278 | BV5: 41.265499 | BW5: 10.379722 | BX5: 1.4391667 | BY5: 29.376216 | BZ5: 10.538889 | CA5: 16.215795 | CB5: 11.763202 | CC5: 0 | CD5: 0 | CE5: 26.686667 | CF5: 10.190833 | CG5: 0.95472222 | CH5: 13.721944 | CI5: 10.735482 | CJ5: 2.1863889 | CK5: Third Hour | CL5: =AVERAGE(B5:CJ5) -> 9.1652591 | CM5: =STDEV(B5:CJ5) -> 11.160098 | CN5: =CM5/SQRT(COUNT(B5:CJ5)) -> 1.2104826
A6: 3 | B6: 14.268854 | C6: 14.753979 | D6: 9.479433 | E6: 7.2756598 | F6: 2.0297222 | G6: 2.0297222 | H6: 0 | I6: 8.1831849 | J6: 6.7694444 | K6: 1.7598403 | L6: 0 | M6: 0 | N6: 5.8841667 | O6: 5.2793995 | P6: 2.2830561 | Q6: 0.77508361 | R6: 15.714604 | S6: 0 | T6: 0.71166667 | U6: 6.1991667 | V6: 8.0522222 | W6: 0 | X6: 8.9966602 | Y6: 0 | Z6: 12.349805 | AB6: 11.960713 | AC6: 7.2427746 | AD6: 0 | AE6: 14.109319 | AF6: 4.465071 | AH6: 0 | AI6: 6.1413889 | AJ6: 32.220367 | AK6: 33.618849 | AL6: 11.249582 | AM6: 0 | AN6: 0 | AO6: 0 | AP6: 0 | AQ6: 13.976382 | AR6: 14.972376 | AS6: 0 | AT6: 0 | AU6: 3.2486802 | AV6: 15.688907 | AW6: 10.40089 | AY6: 8.5611111 | AZ6: 11.955216 | BA6: 6.6230556 | BB6: 5.2838204 | BC6: 0 | BD6: 34.48388 | BE6: 10.058741 | BF6: 19.944429 | BG6: 0 | BH6: 0 | BI6: 0 | BL6: 0.014722222 | BM6: 0 | BN6: 5.0828008 | BO6: 1.3955556 | BP6: 14.1075 | BQ6: 4.46 | BR6: 0 | BT6: 6.1413889 | BU6: 8.0105556 | BV6: 32.215 | BW6: 2.804668 | BX6: 33.615833 | BY6: 3.971087 | BZ6: 11.249444 | CA6: 19.444444 | CB6: 14.798999 | CC6: 0 | CD6: 31.247291 | CE6: 34.728056 | CF6: 23.2275 | CG6: 3.2484023 | CH6: 8.561267 | CI6: 11.955265 | CJ6: 6.6232287 | CK6: End of Perfusion | CL6: =AVERAGE(B6,C6,D20,E6,F13,G13,H9,I16,J8,K21,L13,M14,N15,O12,P20,Q12,R16,S9,T12,U12,V12,W11,X7,Y8,Z6,AB8,AD11,AC7,AE8,AF10,AG5,AH8,AI9,AJ11,AK10,AL9,AM13,AN11,AO11,AP7,AQ7,AR6,AS9,AT13,AU10,AV10,AW22,AY10,AZ10,BA12,BB17,BC8,BD7,BE17,BF11,BG7,BH19,BI10,BJ5,BK5,BL9,BM9,BN14,BO12,BP8,BQ10,BR8,BS5,BT9,BU11,BV11,BW13,BX10,BY17,BZ9,CA21,CB12,CC12,CD12,CE15,CF8,CG10,CH10,CI11,CJ12) -> 10.049925 | CM6: =STDEV(B6,C6,D20,E6,F13,G13,H9,I16,J8,K21,L13,M14,N15,O12,P20,Q12,R16,S9,T12,U12,V12,W11,X7,Y8,Z6,AB8,AD11,AC7,AE8,AF10,AG5,AH8,AI9,AJ11,AK10,AL9,AM13,AN11,AO11,AP7,AQ7,AR6,AS9,AT13,AU10,AV10,AW22,AY10,AZ10,BA12,BB17,BC8,BD7,BE17,BF11,BG7,BH19,BI10,BJ5,BK5,BL9,BM9,BN14,BO12,BP8,BQ10,BR8,BS5,BT9,BU11,BV11,BW13,BX10,BY17,BZ9,CA21,CB12,CC12,CD12,CE15,CF8,CG10,CH10,CI11,CJ12) -> 11.035851 | CN6: =CM6/SQRT(COUNT(B6:CJ6)) -> 1.2262057
A7: 4 | D7: 12.045846 | F7: 0 | G7: 0 | H7: 0 | I7: 8.6057906 | J7: 7.98 | K7: 0 | L7: 0 | M7: 0 | N7: 9.7304251 | O7: 9.2895839 | P7: 0 | Q7: 1.3635854 | R7: 14.12931 | S7: 0 | T7: 5.8286111 | U7: 5.9680378 | V7: 3.8480556 | W7: 0 | X7: 8.8485523 | Y7: 0 | AB7: 11.913577 | AC7: 5.6289855 | AD7: 0 | AE7: 16.010842 | AF7: 11.144964 | AH7: 2.852655 | AI7: 6.0588889 | AJ7: 26.71631 | AK7: 33.018086 | AL7: 13.833287 | AM7: 0 | AN7: 0 | AO7: 0 | AP7: 0 | AQ7: 0.85634899 | AS7: 0 | AT7: 0 | AU7: 4.5097222 | AV7: 17.931591 | AW7: 9.8876842 | AY7: 7.9780556 | AZ7: 14.320534 | BA7: 5.3319444 | BB7: 8.5425078 | BC7: 0 | BD7: 29.533571 | BE7: 10.549616 | BF7: 18.740823 | BG7: 0 | BH7: 0 | BI7: 0 | BL7: 2.7863889 | BM7: 0 | BN7: 4.5791667 | BO7: 18.621944 | BP7: 16.01 | BQ7: 11.143651 | BR7: 2.8530556 | BT7: 6.0588889 | BU7: 4.4711111 | BV7: 26.716111 | BW7: 2.3214782 | BX7: 33.016667 | BY7: 9.5563889 | BZ7: 13.833889 | CA7: 11.1995 | CB7: 10.95332 | CC7: 0 | CD7: 58.734722 | CE7: 19.910833 | CF7: 16.109753 | CG7: 4.5093081 | CH7: 7.9780556 | CI7: 14.320367 | CJ7: 5.3319444
A8: 5 | D8: 13.059739 | F8: 0 | G8: 0 | H8: 0 | I8: 7.8184855 | J8: 6.5832282 | K8: 4.093124 | L8: 0.69502363 | M8: 0 | N8: 31.675397 | O8: 6.8629413 | P8: 0 | Q8: 0.057595993 | R8: 9.7478454 | S8: 0 | T8: 5.4041667 | U8: 27.745763 | V8: 0 | W8: 0 | Y8: 0 | AB8: 11.525073 | AD8: 0 | AE8: 14.315529 | AF8: 3.5451002 | AH8: 11.548333 | AI8: 5.4519444 | AJ8: 26.967213 | AK8: 28.983533 | AL8: 20.471898 | AM8: 0 | AN8: 0 | AO8: 0 | AS8: 0 | AT8: 1.0211111 | AU8: 5.8356964 | AV8: 14.284682 | AW8: 9.9522089 | AY8: 7.4472222 | AZ8: 11.05735 | BA8: 4.1102778 | BB8: 20.487896 | BC8: 0 | BE8: 9.2379627 | BF8: 19.430915 | BH8: 0 | BI8: 0 | BL8: 2.1855556 | BM8: 0 | BN8: 4.8991924 | BO8: 20.485278 | BP8: 14.315529 | BQ8: 3.5427778 | BR8: 11.548333 | BT8: 5.4519444 | BU8: 4.0988889 | BV8: 26.967222 | BW8: 3.44 | BX8: 28.983889 | BY8: 0.73166667 | BZ8: 20.473056 | CA8: 11.898056 | CB8: 13.482068 | CC8: 0 | CD8: 50.004444 | CE8: 0.88302306 | CF8: 15.446204 | CG8: 5.8358333 | CH8: 7.4472222 | CI8: 11.057318 | CJ8: 4.1102778
A9: 6 | D9: 12.947562 | F9: 0 | G9: 0 | H9: 0 | I9: 7.7087162 | K9: 6.8272222 | L9: 1.6964634 | M9: 0.80923248 | N9: 64.650891 | O9: 15.0925 | P9: 0 | Q9: 2.7577105 | R9: 0.44855395 | S9: 13.205 | T9: 3.2191667 | U9: 15.369197 | V9: 8.1719444 | W9: 0 | AD9: 0 | AF9: 9.5280868 | AH9: 13.97417 | AI9: 7.9898182 | AJ9: 27.838387 | AK9: 28.087998 | AL9: 24.515418 | AM9: 0 | AN9: 0 | AO9: 0 | AS9: 0 | AT9: 0.48193441 | AU9: 6.9660828 | AV9: 12.696498 | AW9: 10.319155 | AY9: 7.1169444 | AZ9: 9.7023942 | BA9: 5.6852778 | BB9: 21.695 | BE9: 8.093881 | BF9: 20.52279 | BH9: 0 | BI9: 0 | BL9: 1.9984472 | BM9: 0 | BN9: 6.0594775 | BO9: 18.554722 | BQ9: 9.5288889 | BR9: 13.974217 | BT9: 7.9898182 | BU9: 5.1902778 | BV9: 27.838387 | BW9: 3.5833333 | BX9: 28.087778 | BY9: 7.2948041 | BZ9: 24.514819 | CA9: 10.088056 | CB9: 13.730053 | CC9: 0 | CD9: 47.148889 | CE9: 14.106389 | CG9: 6.9663889 | CH9: 7.1169444 | CI9: 9.7022816 | CJ9: 5.6852778
A10: 7 | D10: 12.881045 | F10: 0 | G10: 0 | I10: 8.2132107 | K10: 4.8005556 | L10: 1.4707195 | M10: 1.6776974 | N10: 65 | O10: 25.835049 | P10: 0 | Q10: 2.1789591 | R10: 0 | T10: 4.5688889 | U10: 12.948305 | V10: 15.945833 | W10: 0 | AD10: 0.21043676 | AF10: 11.210084 | AJ10: 26.565229 | AK10: 24.720639 | AM10: 0 | AN10: 0 | AO10: 0 | AT10: 0 | AU10: 7.0965868 | AV10: 12.491181 | AW10: 11.077009 | AY10: 6.3462846 | AZ10: 9.5433027 | BA10: 5.7577105 | BB10: 21.177778 | BE10: 6.6265398 | BF10: 18.603563 | BH10: 0 | BI10: 0 | BN10: 6.6888889 | BO10: 17.716944 | BQ10: 11.209205 | BU10: 8.9786111 | BV10: 26.564601 | BW10: 2.1558333 | BX10: 24.721076 | BY10: 8.7563889 | CA10: 11.016949 | CB10: 13.644704 | CC10: 0 | CD10: 43.309894 | CE10: 20.322222 | CG10: 7.0965868 | CH10: 6.3464529 | CI10: 9.5434057 | CJ10: 5.7573652
A11: 8 | D11: 11.881879 | F11: 0 | G11: 0 | I11: 8.6778056 | K11: 2.155 | L11: 1.560189 | M11: 1.3809789 | N11: 65 | O11: 19.074785 | P11: 0 | Q11: 2.8949416 | R11: 0 | T11: 0.033888889 | U11: 1.0011183 | V11: 7.3330556 | W11: 0 | AD11: 2.3192053 | AJ11: 25.702247 | AM11: 0 | AN11: 0 | AO11: 0 | AT11: 5.3277731 | AW11: 12.320345 | AZ11: 9.9937811 | BA11: 4.5930881 | BB11: 20.807447 | BE11: 7.883021 | BF11: 16.22017 | BH11: 0 | BN11: 6.3323145 | BO11: 17.771111 | BU11: 10.12696 | BV11: 25.702247 | BW11: 2.7404835 | BY11: 9.1605556 | CA11: 11 | CB11: 15.679911 | CC11: 0 | CD11: 31.878056 | CE11: 16.617394 | CI11: 9.9937811 | CJ11: 4.5923868
A12: 9 | D12: 12.300723 | F12: 0 | G12: 0 | I12: 8.4714564 | K12: 0 | L12: 1.2257437 | M12: 0.84185659 | N12: 64.998329 | O12: 15.064033 | P12: 0 | Q12: 0 | R12: 1.057254 | T12: 0 | U12: 1.8480392 | V12: 5.5824687 | AM12: 0 | AN12: 0 | AO12: 0 | AT12: 13.323505 | AW12: 12.600834 | BA12: 3.9966044 | BB12: 28.804668 | BE12: 8.5148487 | BH12: 0 | BN12: 6.7963323 | BO12: 19.129496 | BW12: 1.270075 | BY12: 9 | CA12: 11.386667 | CB12: 13.965261 | CC12: 0 | CD12: 24.048723 | CE12: 15.200556 | CJ12: 3.9966073
A13: 10 | D13: 11.261534 | F13: 0 | G13: 0 | I13: 9 | K13: 0 | L13: 0.99964888 | M13: 0 | N13: 58.866054 | P13: 0 | R13: 9.2414465 | AM13: 0 | AT13: 2.5196305 | AW13: 13.247428 | BB13: 25.366389 | BE13: 8.1826867 | BH13: 0 | BN13: 7.963601 | BW13: 2.929834 | BY13: 9.9080556 | CA13: 9.3597222 | CE13: 14.283889 | CS13: =
A14: 11 | D14: 9.3442714 | I14: 8.717276 | K14: 0.8235621 | M14: 0 | N14: 58.022569 | P14: 0 | R14: 8.675841 | AM14: 0 | AW14: 13.924339 | BB14: 15.058333 | BE14: 6.1487371 | BH14: 0 | BN14: 7.9643653 | BY14: 10.188889 | CA14: 8.4930556 | CE14: 13.404444
A15: 12 | D15: 9.8232351 | I15: 6.31022 | K15: 6.6322957 | N15: 56.376999 | P15: 0 | R15: 13.747219 | AW15: 15.055046 | BB15: 7.8266667 | BE15: 5.9622253 | BH15: 0 | BY15: 9.0511111 | CA15: 8.6702778 | CE15: 12.905797
A16: 13 | D16: 9.2854364 | I16: 5.3044059 | K16: 0 | P16: 0 | R16: 39.61405 | AW16: 12.517654 | BB16: 5.3554753 | BE16: 5.9951923 | BH16: 0 | BY16: 9.2275 | CA16: 8.059461
A17: 14 | D17: 8.2074527 | K17: 0.083217367 | P17: 0 | AW17: 10.592551 | BB17: 4.986413 | BE17: 5.0470508 | BH17: 0 | BY17: 9.564482 | CA17: 8
A18: 15 | D18: 7.479433 | K18: 3.4420613 | P18: 0 | AW18: 9.1451209 | BE18: 4.9883991 | BH18: 0 | CA18: 7.8027778
A19: 16 | D19: 6.5404504 | K19: 0.4874512 | P19: 0 | AW19: 8.8971541 | BH19: 0 | CA19: 7.668519
A20: 17 | D20: 6.9319066 | K20: 0.24568245 | P20: 0 | AW20: 8.4835508 | CA20: 6.62
A21: 18 | K21: 3.4783383 | AW21: 8.9755863 | CA21: 8.6391111
A22: 19 | AW22: 9.9685114
A23: 20
A24: 21
A25: 22
A26: 23
A27: 24
CM1048576: =STDEV(C1048576:CL1048576) -> #DIV/0!

Sheet pH4TP
B1: Files
A2: Hour | B2: 1 | C2: 2 | D2: 3 | E2: 4 | F2: 5 | G2: 6 | H2: 7 | I2: 8 | J2: 9 | K2: 10 | L2: 11 | M2: 12 | N2: 13 | O2: 14 | P2: 15 | Q2: 16 | R2: 17 | S2: 18 | T2: 19 | U2: 20 | V2: 21 | W2: 22 | X2: 23 | Y2: 24 | Z2: 25 | AA2: 26 | AB2: 27 | AC2: 28 | AD2: 29 | AE2: 30 | AF2: 31 | AG2: 32 | AH2: 33 | AI2: 34 | AJ2: 35 | AK2: 36 | AL2: =AK2+1 -> 37 | AM2: =AL2+1 -> 38 | AN2: =AM2+1 -> 39 | AO2: =AN2+1 -> 40 | AP2: =AO2+1 -> 41 | AQ2: =AP2+1 -> 42 | AR2: =AQ2+1 -> 43 | AS2: =AR2+1 -> 44 | ... CJ2: =CI2+1 -> 87 | CK2: HOUR | CL2: MEAN | CM2: SDEV | CN2: STD ERROR
A3: 0 | B3: 7.1576258 | C3: 7.004772 | D3: 7.0031028 | E3: 7.0798649 | F3: 7.064893 | G3: 7.064893 | H3: 7.2481009 | I3: 7.2580489 | J3: 7.2194035 | K3: 7.1848232 | L3: 7.171002 | M3: 7.2054071 | N3: 6.9911667 | O3: 6.9352336 | P3: 7.1578481 | Q3: 7.0835756 | R3: 7.1018849 | S3: 7.0951784 | T3: 6.9216616 | U3: 7.1520311 | V3: 7.2294777 | W3: 7.0114202 | X3: 7.0590213 | Y3: 7.1969922 | Z3: 7.2781107 | AB3: 7.1095444 | AC3: 7.2967242 | AD3: 7.0267185 | AE3: 7.2014341 | AF3: 7.1600362 | AG3: 7.1390164 | AH3: 7.3270876 | AI3: 7.2273663 | AJ3: 7.1984984 | AK3: 7.0864635 | AL3: 7.1849405 | AM3: 7.1783834 | AN3: 7.3029198 | AO3: 7.3754671 | AP3: 6.8992722 | AQ3: 7.2064472 | AR3: 7.1352805 | AS3: 7.1505166 | AT3: 7.0090343 | AU3: 7.0655638 | AV3: 7.1152083 | AW3: 7.0238192 | AY3: 7.1800445 | AZ3: 7.1859944 | BA3: 7.2134195 | BB3: 7.3129483 | BC3: 7.2093063 | BD3: 6.9711297 | BE3: 7.3257577 | BF3: 7.0319839 | BG3: 8.0219069 | BH3: 8.1166699 | BI3: 7.1100001 | BJ3: 7.27197 | BK3: 7.3250528 | BL3: 7.308175 | BM3: 7.1505166 | BN3: 7.0798305 | BO3: 7.1135945 | BP3: 7.2014111 | BQ3: 7.1600889 | BR3: 7.3270139 | BS3: 7.1390417 | BT3: 7.2273152 | BU3: 7.2250352 | BV3: 7.1986222 | BW3: 7.3370028 | BX3: 7.0864444 | BY3: 7.1835283 | BZ3: 7.1843724 | CA3: 7.16788 | CB3: 7.1758422 | CC3: 7.3755306 | CD3: 7.0560395 | CE3: 7.0309437 | CF3: 7.2028206 | CG3: 7.0656086 | CH3: 7.1800639 | CI3: 7.1859755 | CJ3: 7.2133862 | CK3: First Hour | CL3: =AVERAGE(B3:CJ3) -> 7.1782065 | CM3: =STDEV(B3:CJ3) -> 0.17420901 | CN3: =CM3/SQRT(COUNT(B3:CJ3)) -> 0.018895621
A4: 1 | B4: 7.2270575 | C4: 7.2506448 | D4: 7.0672889 | E4: 7.1545416 | F4: 7.1612488 | G4: 7.1612488 | H4: 7.3114004 | I4: 7.3207045 | J4: 7.3139167 | K4: 7.2534223 | L4: 7.2258021 | M4: 7.3609227 | N4: 7.1420039 | O4: 7.1255196 | P4: 7.1612955 | Q4: 7.213245 | R4: 7.1218121 | S4: 7.2238893 | T4: 7.065576 | U4: 7.2825334 | V4: 7.41405 | W4: 7.2503925 | X4: 7.2155302 | Y4: 7.3262743 | Z4: 7.3832389 | AB4: 7.2571752 | AC4: 7.4485115 | AD4: 7.0698608 | AE4: 7.3969444 | AF4: 7.3326086 | AG4: 7.292908 | AH4: 7.5032037 | AI4: 7.3943194 | AJ4: 7.2835188 | AK4: 7.2863533 | AL4: 7.2726622 | AM4: 7.2580695 | AN4: 7.6594162 | AO4: 7.4554467 | AP4: 7.0850917 | AQ4: 7.3169639 | AR4: 7.1877406 | AS4: 7.1793277 | AT4: 7.1381861 | AU4: 7.2077333 | AV4: 7.2509395 | AW4: 7.1921611 | AY4: 7.371975 | AZ4: 7.3485376 | BA4: 7.3760016 | BB4: 7.3781711 | BC4: 7.2654435 | BD4: 7.042438 | BE4: 7.5161693 | BF4: 7.2417854 | BG4: 8.0392823 | BH4: 8.0877834 | BI4: 7.1100001 | BJ4: 7.2706586 | BK4: 7.2582751 | BL4: 7.3948666 | BM4: 7.1793277 | BN4: 7.2279801 | BO4: 7.2985529 | BP4: 7.3969444 | BQ4: 7.3324999 | BR4: 7.5032223 | BS4: 7.2929473 | BT4: 7.3943194 | BU4: 7.2871861 | BV4: 7.2835583 | BW4: 7.4563723 | BX4: 7.2864074 | BY4: 7.3377639 | BZ4: 7.2707639 | CA4: 7.2815389 | CB4: 7.3153266 | CC4: 7.4538026 | CD4: 7.1900794 | CE4: 7.2363584 | CF4: 7.3496888 | CG4: 7.2077333 | CH4: 7.371975 | CI4: 7.3485972 | CJ4: 7.3760111 | CK4: Second Hour | CL4: =AVERAGE(B4:CJ4) -> 7.300977 | CM4: =STDEV(B4:CJ4) -> 0.16473079 | CN4: =CM4/SQRT(COUNT(B4:CJ4)) -> 0.017867563
A5: 2 | B5: 7.2169496 | C5: 7.2789688 | D5: 7.0977828 | E5: 7.1579882 | F5: 7.116048 | G5: 7.116048 | H5: 7.4336815 | I5: 7.3556884 | J5: 7.3010889 | K5: 7.3349333 | L5: 7.1883546 | M5: 7.3006363 | N5: 7.1801147 | O5: 7.1177311 | P5: 7.2397362 | Q5: 7.1631972 | R5: 7.1739472 | S5: 7.2397357 | T5: 7.2396053 | U5: 7.3469447 | V5: 7.4262721 | W5: 7.2630374 | X5: 7.2754959 | Y5: 7.3062868 | Z5: 7.375215 | AB5: 7.2502173 | AC5: 7.4334863 | AD5: 7.214293 | AE5: 7.4643051 | AF5: 7.3224408 | AG5: 7.3550299 | AH5: 7.4466185 | AI5: 7.3808916 | AJ5: 7.2578646 | AK5: 7.3002615 | AL5: 7.3140528 | AM5: 7.3013139 | AN5: 7.6310582 | AO5: 7.5034422 | AP5: 7.0146917 | AQ5: 7.2797862 | AR5: 7.1974039 | AS5: 7.1834694 | AT5: 7.1078827 | AU5: 7.2690492 | AV5: 7.2860874 | AW5: 7.2011444 | AY5: 7.4259639 | AZ5: 7.355471 | BA5: 7.4132471 | BB5: 7.3614324 | BC5: 7.1826936 | BD5: 7.0639917 | BE5: 7.5076913 | BF5: 7.2540847 | BG5: 8.0670573 | BH5: 8.0866499 | BI5: 7.1023683 | BJ5: 7.2498898 | BK5: 7.1129585 | BL5: 7.3861694 | BM5: 7.1834694 | BN5: 7.2002918 | BO5: 7.2339751 | BP5: 7.4643194 | BQ5: 7.3225451 | BR5: 7.4466445 | BS5: 7.3550299 | BT5: 7.3808916 | BU5: 7.3190556 | BV5: 7.2580262 | BW5: 7.4373804 | BX5: 7.3002862 | BY5: 7.3507891 | BZ5: 7.3141194 | CA5: 7.3082758 | CB5: 7.3592328 | CC5: 7.5034603 | CD5: 7.2134741 | CE5: 7.3657555 | CF5: 7.3293528 | CG5: 7.2690528 | CH5: 7.4259639 | CI5: 7.355471 | CJ5: 7.4132471 | CK5: Third Hour | CL5: =AVERAGE(B5:CJ5) -> 7.3134124 | CM5: =STDEV(B5:CJ5) -> 0.16580694 | CN5: =CM5/SQRT(COUNT(B5:CJ5)) -> 0.017984288
A6: 3 | B6: 7.2273755 | C6: 7.3068833 | D6: 7.1048138 | E6: 7.2278844 | F6: 7.1569277 | G6: 7.1569277 | H6: 7.4851863 | I6: 7.3900194 | J6: 7.3315028 | K6: 7.3322875 | L6: 7.2219712 | M6: 7.3402974 | N6: 7.1572832 | O6: 7.1845954 | P6: 7.345881 | Q6: 7.1815579 | R6: 7.1755076 | S6: 7.2934319 | T6: 7.3102278 | U6: 7.3043528 | V6: 7.4271277 | W6: 7.2442265 | X6: 7.2688144 | Y6: 7.2883523 | Z6: 7.3375226 | AB6: 7.2523461 | AC6: 7.3879768 | AD6: 7.2989324 | AE6: 7.4204116 | AF6: 7.3115642 | AH6: 7.5207787 | AI6: 7.392125 | AJ6: 7.2368948 | AK6: 7.2984626 | AL6: 7.3303009 | AM6: 7.3387556 | AN6: 7.6150861 | AO6: 7.5012936 | AP6: 7.2380445 | AQ6: 7.2903557 | AR6: 7.2631491 | AS6: 7.1483276 | AT6: 7.2026966 | AU6: 7.2525314 | AV6: 7.3620517 | AW6: 7.253414 | AY6: 7.4157611 | AZ6: 7.3779249 | BA6: 7.3874777 | BB6: 7.4084694 | BC6: 7.2094166 | BD6: 7.1077042 | BE6: 7.468014 | BF6: 7.2449515 | BG6: 8.045739 | BH6: 8.0943223 | BI6: 7.0561555 | BL6: 7.37905 | BM6: 7.1483276 | BN6: 7.2433789 | BO6: 7.2676139 | BP6: 7.4205193 | BQ6: 7.3095889 | BR6: 7.5208195 | BT6: 7.392125 | BU6: 7.3405889 | BV6: 7.2370306 | BW6: 7.4289691 | BX6: 7.2985055 | BY6: 7.3237253 | BZ6: 7.3303889 | CA6: 7.363125 | CB6: 7.3775479 | CC6: 7.5015814 | CD6: 7.1983301 | CE6: 7.3899305 | CF6: 7.3273557 | CG6: 7.2525314 | CH6: 7.4157572 | CI6: 7.3779883 | CJ6: 7.3874659 | CK6: End of Perfusion | CL6: =AVERAGE(B6,C6,D20,E6,F13,G13,H9,I16,J8,K21,L13,M14,N15,O12,P20,Q12,R16,S9,T12,U12,V12,W11,X7,Y8,Z6,AB8,AD11,AC7,AE8,AF10,AG5,AH8,AI9,AJ11,AK10,AL9,AM13,AN11,AO11,AP7,AQ7,AR6,AS9,AT13,AU10,AV10,AW22,AY10,AZ10,BA12,BB17,BC8,BD7,BE17,BF11,BG7,BH19,BI10,BJ5,BK5,BL9,BM9,BN14,BO12,BP8,BQ10,BR8,BS5,BT9,BU11,BV11,BW13,BX10,BY17,BZ9,CA21,CB12,CC12,CD12,CE15,CF8,CG10,CH10,CI11,CJ12) -> 7.3465526 | CM6: =STDEV(B6,C6,D20,E6,F13,G13,H9,I16,J8,K21,L13,M14,N15,O12,P20,Q12,R16,S9,T12,U12,V12,W11,X7,Y8,Z6,AB8,AD11,AC7,AE8,AF10,AG5,AH8,AI9,AJ11,AK10,AL9,AM13,AN11,AO11,AP7,AQ7,AR6,AS9,AT13,AU10,AV10,AW22,AY10,AZ10,BA12,BB17,BC8,BD7,BE17,BF11,BG7,BH19,BI10,BJ5,BK5,BL9,BM9,BN14,BO12,BP8,BQ10,BR8,BS5,BT9,BU11,BV11,BW13,BX10,BY17,BZ9,CA21,CB12,CC12,CD12,CE15,CF8,CG10,CH10,CI11,CJ12) -> 0.15031908 | CN6: =CM6/SQRT(COUNT(B6:CJ6)) -> 0.01670212
A7: 4 | D7: 7.1354848 | F7: 7.2258472 | G7: 7.2258472 | H7: 7.4981687 | I7: 7.4019793 | J7: 7.3355278 | K7: 7.3142607 | L7: 7.2422575 | M7: 7.3629505 | N7: 7.23059 | O7: 7.2256269 | P7: 7.3616353 | Q7: 7.1872492 | R7: 7.2110762 | S7: 7.3025611 | T7: 7.3067222 | U7: 7.3372818 | V7: 7.4351194 | W7: 7.2748498 | X7: 7.3012473 | Y7: 7.2974208 | AB7: 7.3596292 | AC7: 7.4583189 | AD7: 7.3016165 | AE7: 7.4562248 | AF7: 7.3398804 | AH7: 7.4887463 | AI7: 7.4217249 | AJ7: 7.2829731 | AK7: 7.2928826 | AL7: 7.2747203 | AM7: 7.2748611 | AN7: 7.5936694 | AO7: 7.5059731 | AP7: 7.2109923 | AQ7: 7.2866491 | AS7: 7.1848888 | AT7: 7.1997802 | AU7: 7.2518723 | AV7: 7.3717436 | AW7: 7.2420435 | AY7: 7.4275194 | AZ7: 7.3993655 | BA7: 7.4162194 | BB7: 7.4280892 | BC7: 7.192661 | BD7: 7.1492334 | BE7: 7.4049786 | BF7: 7.2550752 | BG7: 7.7187987 | BH7: 8.0125167 | BI7: 7.1482 | BL7: 7.3469443 | BM7: 7.1848888 | BN7: 7.2260168 | BO7: 7.3431083 | BP7: 7.456264 | BQ7: 7.3399528 | BR7: 7.4887973 | BT7: 7.4217249 | BU7: 7.3311806 | BV7: 7.2829889 | BW7: 7.4085746 | BX7: 7.2929472 | BY7: 7.3136555 | BZ7: 7.2748611 | CA7: 7.3378188 | CB7: 7.3200222 | CC7: 7.5039445 | CD7: 7.2136169 | CE7: 7.4088916 | CF7: 7.3206335 | CG7: 7.2518506 | CH7: 7.4275194 | CI7: 7.3994303 | CJ7: 7.4162194
A8: 5 | D8: 7.0895915 | F8: 7.2274826 | G8: 7.2274826 | H8: 7.4205343 | I8: 7.4320461 | J8: 7.3895271 | K8: 7.2127341 | L8: 7.2573061 | M8: 7.3721672 | N8: 7.2462052 | O8: 7.2309258 | P8: 7.3856601 | Q8: 7.2027601 | R8: 7.2485294 | S8: 7.2213917 | T8: 7.2817806 | U8: 7.3957432 | V8: 7.4347971 | W8: 7.3427257 | Y8: 7.3355292 | AB8: 7.3899649 | AD8: 7.2891287 | AE8: 7.395905 | AF8: 7.380476 | AH8: 7.4542445 | AI8: 7.4474335 | AJ8: 7.2872354 | AK8: 7.31717 | AL8: 7.3430273 | AM8: 7.3285972 | AN8: 7.5804444 | AO8: 7.5592769 | AQ8: 7.2780097 | AS8: 7.1945527 | AT8: 7.2088472 | AU8: 7.2998694 | AV8: 7.3792771 | AW8: 7.2011365 | AY8: 7.4505777 | AZ8: 7.4266424 | BA8: 7.4191222 | BB8: 7.4690936 | BC8: 7.1831602 | BE8: 7.2765712 | BF8: 7.2520435 | BH8: 8.0622722 | BI8: 7.1498778 | BL8: 7.3716778 | BM8: 7.1945527 | BN8: 7.2819549 | BO8: 7.3592139 | BP8: 7.395905 | BQ8: 7.3805333 | BR8: 7.4542445 | BT8: 7.4474335 | BU8: 7.3046749 | BV8: 7.2872528 | BW8: 7.443936 | BX8: 7.3173862 | BY8: 7.2959195 | BZ8: 7.3430917 | CA8: 7.3658361 | CB8: 7.4145676 | CC8: 7.5564695 | CD8: 7.2204252 | CE8: 7.3919255 | CF8: 7.2698603 | CG8: 7.2999112 | CH8: 7.4505777 | CI8: 7.4266582 | CJ8: 7.4191222
A9: 6 | D9: 7.1540107 | F9: 7.2719317 | G9: 7.2719317 | H9: 7.4384072 | I9: 7.4762713 | K9: 7.2490723 | L9: 7.2348205 | M9: 7.326599 | N9: 7.2650752 | O9: 7.2787556 | P9: 7.4288832 | Q9: 7.1689581 | R9: 7.2745607 | S9: 7.1898555 | T9: 7.3072834 | U9: 7.4117514 | V9: 7.4205249 | W9: 7.2995181 | AD9: 7.247992 | AF9: 7.338807 | AI9: 7.4717747 | AJ9: 7.3149791 | AK9: 7.2827124 | AL9: 7.3389648 | AM9: 7.5127764 | AN9: 7.5552389 | AO9: 7.5873437 | AS9: 7.2355792 | AT9: 7.2244191 | AU9: 7.3151127 | AV9: 7.360906 | AW9: 7.3034057 | AY9: 7.4410165 | AZ9: 7.4163446 | BA9: 7.4587779 | BB9: 7.2939473 | BE9: 7.2928305 | BF9: 7.2610702 | BH9: 7.9865669 | BI9: 7.1374353 | BL9: 7.4444566 | BM9: 7.2355792 | BN9: 7.2885048 | BO9: 7.4092221 | BQ9: 7.3388861 | BR9: 7.5122284 | BT9: 7.4717747 | BU9: 7.3209111 | BV9: 7.3149791 | BW9: 7.3984972 | BX9: 7.2828723 | BY9: 7.3276994 | BZ9: 7.3390341 | CA9: 7.3508944 | CB9: 7.4144036 | CC9: 7.5873583 | CD9: 7.273475 | CE9: 7.3283472 | CG9: 7.3151501 | CH9: 7.4410165 | CI9: 7.4163716 | CJ9: 7.4587779
A10: 7 | D10: 7.1425931 | F10: 7.2342807 | G10: 7.2342807 | I10: 7.4401644 | K10: 7.2526389 | L10: 7.2260011 | M10: 7.3360873 | N10: 7.2782145 | O10: 7.3019027 | P10: 7.412261 | Q10: 7.2696187 | R10: 7.221925 | T10: 7.1022249 | U10: 7.4315646 | V10: 7.4180305 | W10: 7.3415372 | AD10: 7.2882049 | AF10: 7.274916 | AJ10: 7.2729123 | AK10: 7.2763076 | AM10: 7.4968677 | AN10: 7.5490876 | AO10: 7.5783217 | AT10: 7.2124869 | AU10: 7.3346333 | AV10: 7.3032822 | AW10: 7.311985 | AY10: 7.4403157 | AZ10: 7.4659231 | BA10: 7.5192026 | BB10: 7.3616805 | BE10: 7.3404871 | BF10: 7.206534 | BH10: 7.9789722 | BI10: 7.3 | BN10: 7.2941945 | BO10: 7.3915722 | BQ10: 7.2753138 | BU10: 7.309275 | BV10: 7.2730202 | BW10: 7.4322472 | BX10: 7.2763759 | BY10: 7.3339695 | CA10: 7.3650543 | CB10: 7.4142007 | CC10: 7.5783389 | CD10: 7.3078739 | CE10: 7.3584278 | CG10: 7.3346333 | CH10: 7.4403061 | CI10: 7.4659738 | CJ10: 7.5191968
A11: 8 | D11: 7.1469177 | F11: 7.2336362 | G11: 7.2336362 | I11: 7.3698022 | K11: 7.2363779 | L11: 7.2251266 | M11: 7.3048693 | N11: 7.2669947 | O11: 7.3331415 | P11: 7.3690383 | Q11: 7.1689299 | R11: 7.1925708 | T11: 7.1273667 | U11: 7.4161867 | V11: 7.4044666 | W11: 7.3168022 | AD11: 7.2715233 | AJ11: 7.3302808 | AM11: 7.4011256 | AN11: 7.5288387 | AO11: 7.5637862 | AT11: 7.2118265 | AW11: 7.30855 | AZ11: 7.5888993 | BA11: 7.5514382 | BB11: 7.3316893 | BE11: 7.230142 | BF11: 7.2954475 | BH11: 7.9774666 | BN11: 7.2563573 | BO11: 7.3490222 | BU11: 7.2666708 | BV11: 7.3302808 | BW11: 7.4209473 | BY11: 7.309275 | CA11: 7.3308837 | CB11: 7.4137732 | CC11: 7.5637862 | CD11: 7.242775 | CE11: 7.3358294 | CI11: 7.5888993 | CJ11: 7.5516172
A12: 9 | D12: 7.0718176 | F12: 7.2551419 | G12: 7.2551419 | I12: 7.3804984 | K12: 7.276921 | L12: 7.2115375 | M12: 7.3285493 | N12: 7.2658107 | O12: 7.3369073 | P12: 7.3546985 | Q12: 7.2132641 | R12: 7.1960088 | T12: 7.0554597 | U12: 7.3618138 | V12: 7.4322825 | AM12: 7.4741219 | AN12: 7.531578 | AO12: 7.5422837 | AT12: 7.2460029 | AW12: 7.254509 | BA12: 7.79809 | BB12: 7.3377299 | BE12: 7.187173 | BH12: 8.012061 | BN12: 7.2331176 | BO12: 7.3832733 | BY12: 7.3021195 | CA12: 7.3133805 | CB12: 7.4354093 | CC12: 7.5422837 | CD12: 7.2696661 | CE12: 7.3089861 | CJ12: 7.7981086
A13: 10 | D13: 7.0853891 | F13: 7.2650607 | G13: 7.2650607 | I13: 7.4019275 | K13: 7.2457545 | L13: 7.2142698 | M13: 7.3142206 | N13: 7.2471458 | P13: 7.2882165 | R13: 7.2016662 | AM13: 7.4418156 | AT13: 7.2495152 | AW13: 7.3581401 | BB13: 7.3307694 | BE13: 7.2276695 | BH13: 7.9988053 | BN13: 7.2909059 | BY13: 7.2677112 | CA13: 7.3440111 | CE13: 7.2987667 | CS13: =
A14: 11 | D14: 7.0858092 | I14: 7.4007814 | K14: 7.2115616 | M14: 7.3015338 | N14: 7.2129563 | P14: 7.2844683 | R14: 7.2076843 | AM14: 7.4117923 | AW14: 7.3257245 | BB14: 7.2768139 | BE14: 7.2878984 | BH14: 7.9991448 | BN14: 7.2956347 | BY14: 7.2875528 | CA14: 7.3389416 | CE14: 7.2820889
A15: 12 | D15: 7.2505392 | I15: 7.2649457 | K15: 7.2048749 | N15: 7.239914 | P15: 7.2388234 | R15: 7.1280561 | AW15: 7.2821324 | BB15: 7.2770918 | BE15: 7.2769232 | BH15: 8.0042782 | BY15: 7.28505 | CA15: 7.3344028 | CE15: 7.4165216
A16: 13 | D16: 7.2580935 | I16: 7.3129373 | K16: 7.2184516 | P16: 7.2035745 | R16: 7.18029 | AW16: 7.2970893 | BB16: 7.2853669 | BE16: 7.2918841 | BH16: 7.9921804 | BY16: 7.2737139 | CA16: 7.3224895
A17: 14 | D17: 7.2172443 | K17: 7.2393489 | P17: 7.1950209 | AW17: 7.2157087 | BB17: 7.3025273 | BE17: 7.2911389 | BH17: 7.9577166 | BY17: 7.2760466 | CA17: 7.3253334
A18: 15 | D18: 7.2088854 | K18: 7.1738496 | P18: 7.1484982 | AW18: 7.1610842 | BE18: 7.3059398 | BH18: 7.9974006 | CA18: 7.3079862
A19: 16 | D19: 7.1946649 | K19: 7.2006331 | P19: 7.1450138 | AW19: 7.3417723 | BH19: 8.007529 | CA19: 7.2820923
A20: 17 | D20: 7.1658504 | K20: 7.2179054 | P20: 7.2293471 | AW20: 7.3868746 | CA20: 7.2875251
A21: 18 | D21: 7.2392053 | K21: 7.2118873 | AW21: 7.3388051 | CA21: 7.3196711
A22: 19 | AW22: 7.2880407
A23: 20
A24: 21
A25: 22
A26: 23
A27: 24
CM1048576: =STDEV(C1048576:CL1048576) -> #DIV/0!

Sheet ArterialFlow4TP
B1: Files
A2: Hour | B2: 1 | C2: 2 | D2: 3 | E2: 4 | F2: 5 | G2: 6 | H2: 7 | I2: 8 | J2: 9 | K2: 10 | L2: 11 | M2: 12 | N2: 13 | O2: 14 | P2: 15 | Q2: 16 | R2: 17 | S2: 18 | T2: 19 | U2: 20 | V2: 21 | W2: 22 | X2: 23 | Y2: 24 | Z2: 25 | AA2: 26 | AB2: 27 | AC2: 28 | AD2: 29 | AE2: 30 | AF2: 31 | AG2: 32 | AH2: 33 | AI2: 34 | AJ2: 35 | AK2: 36 | AL2: =AK2+1 -> 37 | AM2: =AL2+1 -> 38 | AN2: =AM2+1 -> 39 | AO2: =AN2+1 -> 40 | AP2: =AO2+1 -> 41 | AQ2: =AP2+1 -> 42 | AR2: =AQ2+1 -> 43 | AS2: =AR2+1 -> 44 | ... CJ2: =CI2+1 -> 87 | CK2: HOUR | CL2: MEAN | CM2: SDEV | CN2: STD ERROR
